2024-06-02 01:09:51,917 Callback Server Starting
2024-06-02 01:09:51,917 Socket listening on ('127.0.0.1', 37581)
2024-06-02 01:10:04,266 Python Server ready to receive messages
2024-06-02 01:10:04,267 Received command c on object id p0
2024-06-02 01:10:26,743 The number of arrivals to Citigroup has doubled from 0 to 10 at 2015-12-01 07:20:00
2024-06-02 01:10:26,744 The number of arrivals to Citigroup has doubled from 0 to 15 at 2015-12-01 07:10:00
2024-06-02 01:10:26,745 The number of arrivals to Citigroup has doubled from 0 to 10 at 2015-12-01 07:50:00
2024-06-02 01:10:26,745 The number of arrivals to Citigroup has doubled from 0 to 10 at 2015-12-01 14:10:00
2024-06-02 01:10:26,745 The number of arrivals to Citigroup has doubled from 0 to 18 at 2015-12-01 07:00:00
2024-06-02 01:10:26,745 The number of arrivals to Citigroup has doubled from 0 to 16 at 2015-12-01 09:10:00
2024-06-02 01:10:26,745 The number of arrivals to Citigroup has doubled from 0 to 11 at 2015-12-01 08:10:00
2024-06-02 01:10:26,746 The number of arrivals to Goldman Sachs has doubled from 0 to 11 at 2015-12-01 09:30:00
2024-06-02 01:10:26,746 The number of arrivals to Citigroup has doubled from 0 to 10 at 2015-12-01 10:00:00
2024-06-02 01:10:26,746 The number of arrivals to Citigroup has doubled from 0 to 12 at 2015-12-01 09:00:00
2024-06-02 01:10:26,746 The number of arrivals to Citigroup has doubled from 0 to 10 at 2015-12-01 07:30:00
2024-06-02 01:10:26,746 The number of arrivals to Goldman Sachs has doubled from 0 to 10 at 2015-12-01 09:40:00
2024-06-02 01:10:26,746 The number of arrivals to Citigroup has doubled from 0 to 12 at 2015-12-01 09:40:00
2024-06-02 01:10:26,747 The number of arrivals to Citigroup has doubled from 0 to 13 at 2015-12-01 06:50:00
2024-06-02 01:10:26,747 The number of arrivals to Citigroup has doubled from 0 to 14 at 2015-12-01 08:30:00
2024-06-02 01:17:10,546 Error while receiving.
Traceback (most recent call last):
  File "/home/april/spark-3.5.1-bin-hadoop3/python/lib/py4j-0.10.9.7-src.zip/py4j/clientserver.py", line 511, in send_command
    answer = smart_decode(self.stream.readline()[:-1])
RuntimeError: reentrant call inside <_io.BufferedReader name=4>
2024-06-02 01:17:10,546 Closing down clientserver connection
2024-06-02 01:17:10,547 Exception while sending command.
Traceback (most recent call last):
  File "/home/april/spark-3.5.1-bin-hadoop3/python/lib/py4j-0.10.9.7-src.zip/py4j/clientserver.py", line 511, in send_command
    answer = smart_decode(self.stream.readline()[:-1])
RuntimeError: reentrant call inside <_io.BufferedReader name=4>

During handling of the above exception, another exception occurred:

Traceback (most recent call last):
  File "/home/april/spark-3.5.1-bin-hadoop3/python/lib/py4j-0.10.9.7-src.zip/py4j/java_gateway.py", line 1038, in send_command
    response = connection.send_command(command)
  File "/home/april/spark-3.5.1-bin-hadoop3/python/lib/py4j-0.10.9.7-src.zip/py4j/clientserver.py", line 539, in send_command
    raise Py4JNetworkError(
py4j.protocol.Py4JNetworkError: Error while sending or receiving
2024-06-02 01:17:10,549 Error while receiving.
Traceback (most recent call last):
  File "/home/april/spark-3.5.1-bin-hadoop3/python/lib/py4j-0.10.9.7-src.zip/py4j/clientserver.py", line 511, in send_command
    answer = smart_decode(self.stream.readline()[:-1])
  File "/usr/lib/python3.10/socket.py", line 705, in readinto
    return self._sock.recv_into(b)
  File "/home/april/spark-3.5.1-bin-hadoop3/python/lib/pyspark.zip/pyspark/context.py", line 381, in signal_handler
    self.cancelAllJobs()
  File "/home/april/spark-3.5.1-bin-hadoop3/python/lib/pyspark.zip/pyspark/context.py", line 2446, in cancelAllJobs
    self._jsc.sc().cancelAllJobs()
  File "/home/april/spark-3.5.1-bin-hadoop3/python/lib/py4j-0.10.9.7-src.zip/py4j/java_gateway.py", line 1322, in __call__
    return_value = get_return_value(
  File "/home/april/spark-3.5.1-bin-hadoop3/python/lib/pyspark.zip/pyspark/errors/exceptions/captured.py", line 179, in deco
    return f(*a, **kw)
  File "/home/april/spark-3.5.1-bin-hadoop3/python/lib/py4j-0.10.9.7-src.zip/py4j/protocol.py", line 334, in get_return_value
    raise Py4JError(
py4j.protocol.Py4JError: An error occurred while calling o12.sc
2024-06-02 01:17:10,551 Closing down clientserver connection
2024-06-02 01:17:10,551 Exception while sending command.
Traceback (most recent call last):
  File "/home/april/spark-3.5.1-bin-hadoop3/python/lib/py4j-0.10.9.7-src.zip/py4j/clientserver.py", line 511, in send_command
    answer = smart_decode(self.stream.readline()[:-1])
  File "/usr/lib/python3.10/socket.py", line 705, in readinto
    return self._sock.recv_into(b)
  File "/home/april/spark-3.5.1-bin-hadoop3/python/lib/pyspark.zip/pyspark/context.py", line 381, in signal_handler
    self.cancelAllJobs()
  File "/home/april/spark-3.5.1-bin-hadoop3/python/lib/pyspark.zip/pyspark/context.py", line 2446, in cancelAllJobs
    self._jsc.sc().cancelAllJobs()
  File "/home/april/spark-3.5.1-bin-hadoop3/python/lib/py4j-0.10.9.7-src.zip/py4j/java_gateway.py", line 1322, in __call__
    return_value = get_return_value(
  File "/home/april/spark-3.5.1-bin-hadoop3/python/lib/pyspark.zip/pyspark/errors/exceptions/captured.py", line 179, in deco
    return f(*a, **kw)
  File "/home/april/spark-3.5.1-bin-hadoop3/python/lib/py4j-0.10.9.7-src.zip/py4j/protocol.py", line 334, in get_return_value
    raise Py4JError(
py4j.protocol.Py4JError: An error occurred while calling o12.sc

During handling of the above exception, another exception occurred:

Traceback (most recent call last):
  File "/home/april/spark-3.5.1-bin-hadoop3/python/lib/py4j-0.10.9.7-src.zip/py4j/java_gateway.py", line 1038, in send_command
    response = connection.send_command(command)
  File "/home/april/spark-3.5.1-bin-hadoop3/python/lib/py4j-0.10.9.7-src.zip/py4j/clientserver.py", line 539, in send_command
    raise Py4JNetworkError(
py4j.protocol.Py4JNetworkError: Error while sending or receiving
2024-06-02 01:17:10,551 Closing down clientserver connection
2024-06-02 01:17:10,605 Closing down clientserver connection
2024-06-02 15:32:15,579 Callback Server Starting
2024-06-02 15:32:15,579 Socket listening on ('127.0.0.1', 38661)
2024-06-02 15:32:26,179 Python Server ready to receive messages
2024-06-02 15:32:26,179 Received command c on object id p0
2024-06-02 15:32:48,059 The number of arrivals to Citigroup has doubled from 0 to 10 at 2015-12-01 07:20:00
2024-06-02 15:32:48,059 The number of arrivals to Citigroup has doubled from 0 to 15 at 2015-12-01 07:10:00
2024-06-02 15:32:48,059 The number of arrivals to Citigroup has doubled from 0 to 10 at 2015-12-01 07:50:00
2024-06-02 15:32:48,060 The number of arrivals to Citigroup has doubled from 0 to 10 at 2015-12-01 14:10:00
2024-06-02 15:32:48,060 The number of arrivals to Citigroup has doubled from 0 to 18 at 2015-12-01 07:00:00
2024-06-02 15:32:48,060 The number of arrivals to Citigroup has doubled from 0 to 16 at 2015-12-01 09:10:00
2024-06-02 15:32:48,060 The number of arrivals to Citigroup has doubled from 0 to 11 at 2015-12-01 08:10:00
2024-06-02 15:32:48,060 The number of arrivals to Goldman Sachs has doubled from 0 to 11 at 2015-12-01 09:30:00
2024-06-02 15:32:48,060 The number of arrivals to Citigroup has doubled from 0 to 10 at 2015-12-01 10:00:00
2024-06-02 15:32:48,060 The number of arrivals to Citigroup has doubled from 0 to 12 at 2015-12-01 09:00:00
2024-06-02 15:32:48,060 The number of arrivals to Citigroup has doubled from 0 to 10 at 2015-12-01 07:30:00
2024-06-02 15:32:48,060 The number of arrivals to Goldman Sachs has doubled from 0 to 10 at 2015-12-01 09:40:00
2024-06-02 15:32:48,060 The number of arrivals to Citigroup has doubled from 0 to 12 at 2015-12-01 09:40:00
2024-06-02 15:32:48,061 The number of arrivals to Citigroup has doubled from 0 to 13 at 2015-12-01 06:50:00
2024-06-02 15:32:48,061 The number of arrivals to Citigroup has doubled from 0 to 14 at 2015-12-01 08:30:00
2024-06-02 15:34:04,269 Error while receiving.
Traceback (most recent call last):
  File "/home/april/spark-3.5.1-bin-hadoop3/python/lib/py4j-0.10.9.7-src.zip/py4j/clientserver.py", line 511, in send_command
    answer = smart_decode(self.stream.readline()[:-1])
RuntimeError: reentrant call inside <_io.BufferedReader name=4>
2024-06-02 15:34:04,269 Closing down clientserver connection
2024-06-02 15:34:04,270 Exception while sending command.
Traceback (most recent call last):
  File "/home/april/spark-3.5.1-bin-hadoop3/python/lib/py4j-0.10.9.7-src.zip/py4j/clientserver.py", line 511, in send_command
    answer = smart_decode(self.stream.readline()[:-1])
RuntimeError: reentrant call inside <_io.BufferedReader name=4>

During handling of the above exception, another exception occurred:

Traceback (most recent call last):
  File "/home/april/spark-3.5.1-bin-hadoop3/python/lib/py4j-0.10.9.7-src.zip/py4j/java_gateway.py", line 1038, in send_command
    response = connection.send_command(command)
  File "/home/april/spark-3.5.1-bin-hadoop3/python/lib/py4j-0.10.9.7-src.zip/py4j/clientserver.py", line 539, in send_command
    raise Py4JNetworkError(
py4j.protocol.Py4JNetworkError: Error while sending or receiving
2024-06-02 15:34:04,273 Error while receiving.
Traceback (most recent call last):
  File "/home/april/spark-3.5.1-bin-hadoop3/python/lib/py4j-0.10.9.7-src.zip/py4j/clientserver.py", line 511, in send_command
    answer = smart_decode(self.stream.readline()[:-1])
  File "/usr/lib/python3.10/socket.py", line 705, in readinto
    return self._sock.recv_into(b)
  File "/home/april/spark-3.5.1-bin-hadoop3/python/lib/pyspark.zip/pyspark/context.py", line 381, in signal_handler
    self.cancelAllJobs()
  File "/home/april/spark-3.5.1-bin-hadoop3/python/lib/pyspark.zip/pyspark/context.py", line 2446, in cancelAllJobs
    self._jsc.sc().cancelAllJobs()
  File "/home/april/spark-3.5.1-bin-hadoop3/python/lib/py4j-0.10.9.7-src.zip/py4j/java_gateway.py", line 1322, in __call__
    return_value = get_return_value(
  File "/home/april/spark-3.5.1-bin-hadoop3/python/lib/pyspark.zip/pyspark/errors/exceptions/captured.py", line 179, in deco
    return f(*a, **kw)
  File "/home/april/spark-3.5.1-bin-hadoop3/python/lib/py4j-0.10.9.7-src.zip/py4j/protocol.py", line 334, in get_return_value
    raise Py4JError(
py4j.protocol.Py4JError: An error occurred while calling o12.sc
2024-06-02 15:34:04,276 Closing down clientserver connection
2024-06-02 15:34:04,276 Exception while sending command.
Traceback (most recent call last):
  File "/home/april/spark-3.5.1-bin-hadoop3/python/lib/py4j-0.10.9.7-src.zip/py4j/clientserver.py", line 511, in send_command
    answer = smart_decode(self.stream.readline()[:-1])
  File "/usr/lib/python3.10/socket.py", line 705, in readinto
    return self._sock.recv_into(b)
  File "/home/april/spark-3.5.1-bin-hadoop3/python/lib/pyspark.zip/pyspark/context.py", line 381, in signal_handler
    self.cancelAllJobs()
  File "/home/april/spark-3.5.1-bin-hadoop3/python/lib/pyspark.zip/pyspark/context.py", line 2446, in cancelAllJobs
    self._jsc.sc().cancelAllJobs()
  File "/home/april/spark-3.5.1-bin-hadoop3/python/lib/py4j-0.10.9.7-src.zip/py4j/java_gateway.py", line 1322, in __call__
    return_value = get_return_value(
  File "/home/april/spark-3.5.1-bin-hadoop3/python/lib/pyspark.zip/pyspark/errors/exceptions/captured.py", line 179, in deco
    return f(*a, **kw)
  File "/home/april/spark-3.5.1-bin-hadoop3/python/lib/py4j-0.10.9.7-src.zip/py4j/protocol.py", line 334, in get_return_value
    raise Py4JError(
py4j.protocol.Py4JError: An error occurred while calling o12.sc

During handling of the above exception, another exception occurred:

Traceback (most recent call last):
  File "/home/april/spark-3.5.1-bin-hadoop3/python/lib/py4j-0.10.9.7-src.zip/py4j/java_gateway.py", line 1038, in send_command
    response = connection.send_command(command)
  File "/home/april/spark-3.5.1-bin-hadoop3/python/lib/py4j-0.10.9.7-src.zip/py4j/clientserver.py", line 539, in send_command
    raise Py4JNetworkError(
py4j.protocol.Py4JNetworkError: Error while sending or receiving
2024-06-02 15:34:04,277 Closing down clientserver connection
2024-06-02 15:34:04,351 Closing down clientserver connection
2024-06-02 15:43:18,684 Closing down clientserver connection
2024-06-02 15:45:33,098 Callback Server Starting
2024-06-02 15:45:33,098 Socket listening on ('127.0.0.1', 45055)
2024-06-02 15:45:42,515 Python Server ready to receive messages
2024-06-02 15:45:42,515 Received command c on object id p0
2024-06-02 15:46:01,858 The number of arrivals to Citigroup has doubled from 0 to 10 at 2015-12-01 07:20:00
2024-06-02 15:46:01,858 The number of arrivals to Citigroup has doubled from 0 to 15 at 2015-12-01 07:10:00
2024-06-02 15:46:01,858 The number of arrivals to Citigroup has doubled from 0 to 10 at 2015-12-01 07:50:00
2024-06-02 15:46:01,858 The number of arrivals to Citigroup has doubled from 0 to 10 at 2015-12-01 14:10:00
2024-06-02 15:46:01,859 The number of arrivals to Citigroup has doubled from 0 to 18 at 2015-12-01 07:00:00
2024-06-02 15:46:01,859 The number of arrivals to Citigroup has doubled from 0 to 16 at 2015-12-01 09:10:00
2024-06-02 15:46:01,859 The number of arrivals to Citigroup has doubled from 0 to 11 at 2015-12-01 08:10:00
2024-06-02 15:46:01,859 The number of arrivals to Goldman Sachs has doubled from 0 to 11 at 2015-12-01 09:30:00
2024-06-02 15:46:01,859 The number of arrivals to Citigroup has doubled from 0 to 10 at 2015-12-01 10:00:00
2024-06-02 15:46:01,859 The number of arrivals to Citigroup has doubled from 0 to 12 at 2015-12-01 09:00:00
2024-06-02 15:46:01,859 The number of arrivals to Citigroup has doubled from 0 to 10 at 2015-12-01 07:30:00
2024-06-02 15:46:01,860 The number of arrivals to Goldman Sachs has doubled from 0 to 10 at 2015-12-01 09:40:00
2024-06-02 15:46:01,860 The number of arrivals to Citigroup has doubled from 0 to 12 at 2015-12-01 09:40:00
2024-06-02 15:46:01,860 The number of arrivals to Citigroup has doubled from 0 to 13 at 2015-12-01 06:50:00
2024-06-02 15:46:01,860 The number of arrivals to Citigroup has doubled from 0 to 14 at 2015-12-01 08:30:00
2024-06-02 15:48:04,602 Error while receiving.
Traceback (most recent call last):
  File "/home/april/spark-3.5.1-bin-hadoop3/python/lib/py4j-0.10.9.7-src.zip/py4j/clientserver.py", line 511, in send_command
    answer = smart_decode(self.stream.readline()[:-1])
RuntimeError: reentrant call inside <_io.BufferedReader name=4>
2024-06-02 15:48:04,603 Closing down clientserver connection
2024-06-02 15:48:04,603 Exception while sending command.
Traceback (most recent call last):
  File "/home/april/spark-3.5.1-bin-hadoop3/python/lib/py4j-0.10.9.7-src.zip/py4j/clientserver.py", line 511, in send_command
    answer = smart_decode(self.stream.readline()[:-1])
RuntimeError: reentrant call inside <_io.BufferedReader name=4>

During handling of the above exception, another exception occurred:

Traceback (most recent call last):
  File "/home/april/spark-3.5.1-bin-hadoop3/python/lib/py4j-0.10.9.7-src.zip/py4j/java_gateway.py", line 1038, in send_command
    response = connection.send_command(command)
  File "/home/april/spark-3.5.1-bin-hadoop3/python/lib/py4j-0.10.9.7-src.zip/py4j/clientserver.py", line 539, in send_command
    raise Py4JNetworkError(
py4j.protocol.Py4JNetworkError: Error while sending or receiving
2024-06-02 15:48:04,605 Error while receiving.
Traceback (most recent call last):
  File "/home/april/spark-3.5.1-bin-hadoop3/python/lib/py4j-0.10.9.7-src.zip/py4j/clientserver.py", line 511, in send_command
    answer = smart_decode(self.stream.readline()[:-1])
  File "/usr/lib/python3.10/socket.py", line 705, in readinto
    return self._sock.recv_into(b)
  File "/home/april/spark-3.5.1-bin-hadoop3/python/lib/pyspark.zip/pyspark/context.py", line 381, in signal_handler
    self.cancelAllJobs()
  File "/home/april/spark-3.5.1-bin-hadoop3/python/lib/pyspark.zip/pyspark/context.py", line 2446, in cancelAllJobs
    self._jsc.sc().cancelAllJobs()
  File "/home/april/spark-3.5.1-bin-hadoop3/python/lib/py4j-0.10.9.7-src.zip/py4j/java_gateway.py", line 1322, in __call__
    return_value = get_return_value(
  File "/home/april/spark-3.5.1-bin-hadoop3/python/lib/pyspark.zip/pyspark/errors/exceptions/captured.py", line 179, in deco
    return f(*a, **kw)
  File "/home/april/spark-3.5.1-bin-hadoop3/python/lib/py4j-0.10.9.7-src.zip/py4j/protocol.py", line 334, in get_return_value
    raise Py4JError(
py4j.protocol.Py4JError: An error occurred while calling o12.sc
2024-06-02 15:48:04,607 Closing down clientserver connection
2024-06-02 15:48:04,607 Exception while sending command.
Traceback (most recent call last):
  File "/home/april/spark-3.5.1-bin-hadoop3/python/lib/py4j-0.10.9.7-src.zip/py4j/clientserver.py", line 511, in send_command
    answer = smart_decode(self.stream.readline()[:-1])
  File "/usr/lib/python3.10/socket.py", line 705, in readinto
    return self._sock.recv_into(b)
  File "/home/april/spark-3.5.1-bin-hadoop3/python/lib/pyspark.zip/pyspark/context.py", line 381, in signal_handler
    self.cancelAllJobs()
  File "/home/april/spark-3.5.1-bin-hadoop3/python/lib/pyspark.zip/pyspark/context.py", line 2446, in cancelAllJobs
    self._jsc.sc().cancelAllJobs()
  File "/home/april/spark-3.5.1-bin-hadoop3/python/lib/py4j-0.10.9.7-src.zip/py4j/java_gateway.py", line 1322, in __call__
    return_value = get_return_value(
  File "/home/april/spark-3.5.1-bin-hadoop3/python/lib/pyspark.zip/pyspark/errors/exceptions/captured.py", line 179, in deco
    return f(*a, **kw)
  File "/home/april/spark-3.5.1-bin-hadoop3/python/lib/py4j-0.10.9.7-src.zip/py4j/protocol.py", line 334, in get_return_value
    raise Py4JError(
py4j.protocol.Py4JError: An error occurred while calling o12.sc

During handling of the above exception, another exception occurred:

Traceback (most recent call last):
  File "/home/april/spark-3.5.1-bin-hadoop3/python/lib/py4j-0.10.9.7-src.zip/py4j/java_gateway.py", line 1038, in send_command
    response = connection.send_command(command)
  File "/home/april/spark-3.5.1-bin-hadoop3/python/lib/py4j-0.10.9.7-src.zip/py4j/clientserver.py", line 539, in send_command
    raise Py4JNetworkError(
py4j.protocol.Py4JNetworkError: Error while sending or receiving
2024-06-02 15:48:04,607 Closing down clientserver connection
2024-06-02 15:48:04,650 Closing down clientserver connection
2024-06-02 15:48:12,134 Callback Server Starting
2024-06-02 15:48:12,134 Socket listening on ('127.0.0.1', 33329)
2024-06-02 15:48:25,898 Python Server ready to receive messages
2024-06-02 15:48:25,898 Received command c on object id p0
2024-06-02 15:49:04,894 The number of arrivals to Citigroup has doubled from 0 to 10 at 2015-12-01 07:20:00
2024-06-02 15:49:04,894 The number of arrivals to Citigroup has doubled from 0 to 15 at 2015-12-01 07:10:00
2024-06-02 15:49:04,894 The number of arrivals to Citigroup has doubled from 0 to 10 at 2015-12-01 07:50:00
2024-06-02 15:49:04,894 The number of arrivals to Citigroup has doubled from 0 to 10 at 2015-12-01 14:10:00
2024-06-02 15:49:04,894 The number of arrivals to Citigroup has doubled from 0 to 18 at 2015-12-01 07:00:00
2024-06-02 15:49:04,895 The number of arrivals to Citigroup has doubled from 0 to 16 at 2015-12-01 09:10:00
2024-06-02 15:49:04,895 The number of arrivals to Citigroup has doubled from 0 to 11 at 2015-12-01 08:10:00
2024-06-02 15:49:04,895 The number of arrivals to Goldman Sachs has doubled from 0 to 11 at 2015-12-01 09:30:00
2024-06-02 15:49:04,895 The number of arrivals to Citigroup has doubled from 0 to 10 at 2015-12-01 10:00:00
2024-06-02 15:49:04,895 The number of arrivals to Citigroup has doubled from 0 to 12 at 2015-12-01 09:00:00
2024-06-02 15:49:04,895 The number of arrivals to Citigroup has doubled from 0 to 10 at 2015-12-01 07:30:00
2024-06-02 15:49:04,895 The number of arrivals to Goldman Sachs has doubled from 0 to 10 at 2015-12-01 09:40:00
2024-06-02 15:49:04,895 The number of arrivals to Citigroup has doubled from 0 to 12 at 2015-12-01 09:40:00
2024-06-02 15:49:04,895 The number of arrivals to Citigroup has doubled from 0 to 13 at 2015-12-01 06:50:00
2024-06-02 15:49:04,895 The number of arrivals to Citigroup has doubled from 0 to 14 at 2015-12-01 08:30:00
2024-06-02 15:49:07,372 Error while receiving.
Traceback (most recent call last):
  File "/home/april/spark-3.5.1-bin-hadoop3/python/lib/py4j-0.10.9.7-src.zip/py4j/clientserver.py", line 511, in send_command
    answer = smart_decode(self.stream.readline()[:-1])
RuntimeError: reentrant call inside <_io.BufferedReader name=4>
2024-06-02 15:49:07,373 Closing down clientserver connection
2024-06-02 15:49:07,373 Exception while sending command.
Traceback (most recent call last):
  File "/home/april/spark-3.5.1-bin-hadoop3/python/lib/py4j-0.10.9.7-src.zip/py4j/clientserver.py", line 511, in send_command
    answer = smart_decode(self.stream.readline()[:-1])
RuntimeError: reentrant call inside <_io.BufferedReader name=4>

During handling of the above exception, another exception occurred:

Traceback (most recent call last):
  File "/home/april/spark-3.5.1-bin-hadoop3/python/lib/py4j-0.10.9.7-src.zip/py4j/java_gateway.py", line 1038, in send_command
    response = connection.send_command(command)
  File "/home/april/spark-3.5.1-bin-hadoop3/python/lib/py4j-0.10.9.7-src.zip/py4j/clientserver.py", line 539, in send_command
    raise Py4JNetworkError(
py4j.protocol.Py4JNetworkError: Error while sending or receiving
2024-06-02 15:49:07,374 Error while receiving.
Traceback (most recent call last):
  File "/home/april/spark-3.5.1-bin-hadoop3/python/lib/py4j-0.10.9.7-src.zip/py4j/clientserver.py", line 511, in send_command
    answer = smart_decode(self.stream.readline()[:-1])
  File "/usr/lib/python3.10/socket.py", line 705, in readinto
    return self._sock.recv_into(b)
  File "/home/april/spark-3.5.1-bin-hadoop3/python/lib/pyspark.zip/pyspark/context.py", line 381, in signal_handler
    self.cancelAllJobs()
  File "/home/april/spark-3.5.1-bin-hadoop3/python/lib/pyspark.zip/pyspark/context.py", line 2446, in cancelAllJobs
    self._jsc.sc().cancelAllJobs()
  File "/home/april/spark-3.5.1-bin-hadoop3/python/lib/py4j-0.10.9.7-src.zip/py4j/java_gateway.py", line 1322, in __call__
    return_value = get_return_value(
  File "/home/april/spark-3.5.1-bin-hadoop3/python/lib/pyspark.zip/pyspark/errors/exceptions/captured.py", line 179, in deco
    return f(*a, **kw)
  File "/home/april/spark-3.5.1-bin-hadoop3/python/lib/py4j-0.10.9.7-src.zip/py4j/protocol.py", line 334, in get_return_value
    raise Py4JError(
py4j.protocol.Py4JError: An error occurred while calling o12.sc
2024-06-02 15:49:07,375 Closing down clientserver connection
2024-06-02 15:49:07,375 Exception while sending command.
Traceback (most recent call last):
  File "/home/april/spark-3.5.1-bin-hadoop3/python/lib/py4j-0.10.9.7-src.zip/py4j/clientserver.py", line 511, in send_command
    answer = smart_decode(self.stream.readline()[:-1])
  File "/usr/lib/python3.10/socket.py", line 705, in readinto
    return self._sock.recv_into(b)
  File "/home/april/spark-3.5.1-bin-hadoop3/python/lib/pyspark.zip/pyspark/context.py", line 381, in signal_handler
    self.cancelAllJobs()
  File "/home/april/spark-3.5.1-bin-hadoop3/python/lib/pyspark.zip/pyspark/context.py", line 2446, in cancelAllJobs
    self._jsc.sc().cancelAllJobs()
  File "/home/april/spark-3.5.1-bin-hadoop3/python/lib/py4j-0.10.9.7-src.zip/py4j/java_gateway.py", line 1322, in __call__
    return_value = get_return_value(
  File "/home/april/spark-3.5.1-bin-hadoop3/python/lib/pyspark.zip/pyspark/errors/exceptions/captured.py", line 179, in deco
    return f(*a, **kw)
  File "/home/april/spark-3.5.1-bin-hadoop3/python/lib/py4j-0.10.9.7-src.zip/py4j/protocol.py", line 334, in get_return_value
    raise Py4JError(
py4j.protocol.Py4JError: An error occurred while calling o12.sc

During handling of the above exception, another exception occurred:

Traceback (most recent call last):
  File "/home/april/spark-3.5.1-bin-hadoop3/python/lib/py4j-0.10.9.7-src.zip/py4j/java_gateway.py", line 1038, in send_command
    response = connection.send_command(command)
  File "/home/april/spark-3.5.1-bin-hadoop3/python/lib/py4j-0.10.9.7-src.zip/py4j/clientserver.py", line 539, in send_command
    raise Py4JNetworkError(
py4j.protocol.Py4JNetworkError: Error while sending or receiving
2024-06-02 15:49:07,375 Closing down clientserver connection
2024-06-02 15:49:07,436 Closing down clientserver connection
2024-06-02 15:51:33,037 Closing down clientserver connection
2024-06-02 15:51:55,940 Closing down clientserver connection
2024-06-02 15:52:11,971 Callback Server Starting
2024-06-02 15:52:11,972 Socket listening on ('127.0.0.1', 44213)
2024-06-02 15:52:27,014 Python Server ready to receive messages
2024-06-02 15:52:27,014 Received command c on object id p0
2024-06-02 15:53:08,487 The number of arrivals to Citigroup has doubled from 0 to 10 at 2015-12-01 07:20:00
2024-06-02 15:53:08,487 The number of arrivals to Citigroup has doubled from 0 to 15 at 2015-12-01 07:10:00
2024-06-02 15:53:08,487 The number of arrivals to Citigroup has doubled from 0 to 10 at 2015-12-01 07:50:00
2024-06-02 15:53:08,488 The number of arrivals to Citigroup has doubled from 0 to 10 at 2015-12-01 14:10:00
2024-06-02 15:53:08,488 The number of arrivals to Citigroup has doubled from 0 to 18 at 2015-12-01 07:00:00
2024-06-02 15:53:08,488 The number of arrivals to Citigroup has doubled from 0 to 16 at 2015-12-01 09:10:00
2024-06-02 15:53:08,488 The number of arrivals to Citigroup has doubled from 0 to 11 at 2015-12-01 08:10:00
2024-06-02 15:53:08,488 The number of arrivals to Goldman Sachs has doubled from 0 to 11 at 2015-12-01 09:30:00
2024-06-02 15:53:08,488 The number of arrivals to Citigroup has doubled from 0 to 10 at 2015-12-01 10:00:00
2024-06-02 15:53:08,488 The number of arrivals to Citigroup has doubled from 0 to 12 at 2015-12-01 09:00:00
2024-06-02 15:53:08,488 The number of arrivals to Citigroup has doubled from 0 to 10 at 2015-12-01 07:30:00
2024-06-02 15:53:08,488 The number of arrivals to Goldman Sachs has doubled from 0 to 10 at 2015-12-01 09:40:00
2024-06-02 15:53:08,488 The number of arrivals to Citigroup has doubled from 0 to 12 at 2015-12-01 09:40:00
2024-06-02 15:53:08,488 The number of arrivals to Citigroup has doubled from 0 to 13 at 2015-12-01 06:50:00
2024-06-02 15:53:08,488 The number of arrivals to Citigroup has doubled from 0 to 14 at 2015-12-01 08:30:00
2024-06-02 15:53:12,271 Error while receiving.
Traceback (most recent call last):
  File "/home/april/spark-3.5.1-bin-hadoop3/python/lib/py4j-0.10.9.7-src.zip/py4j/clientserver.py", line 511, in send_command
    answer = smart_decode(self.stream.readline()[:-1])
RuntimeError: reentrant call inside <_io.BufferedReader name=4>
2024-06-02 15:53:12,272 Closing down clientserver connection
2024-06-02 15:53:12,272 Exception while sending command.
Traceback (most recent call last):
  File "/home/april/spark-3.5.1-bin-hadoop3/python/lib/py4j-0.10.9.7-src.zip/py4j/clientserver.py", line 511, in send_command
    answer = smart_decode(self.stream.readline()[:-1])
RuntimeError: reentrant call inside <_io.BufferedReader name=4>

During handling of the above exception, another exception occurred:

Traceback (most recent call last):
  File "/home/april/spark-3.5.1-bin-hadoop3/python/lib/py4j-0.10.9.7-src.zip/py4j/java_gateway.py", line 1038, in send_command
    response = connection.send_command(command)
  File "/home/april/spark-3.5.1-bin-hadoop3/python/lib/py4j-0.10.9.7-src.zip/py4j/clientserver.py", line 539, in send_command
    raise Py4JNetworkError(
py4j.protocol.Py4JNetworkError: Error while sending or receiving
2024-06-02 15:53:12,273 Error while receiving.
Traceback (most recent call last):
  File "/home/april/spark-3.5.1-bin-hadoop3/python/lib/py4j-0.10.9.7-src.zip/py4j/clientserver.py", line 511, in send_command
    answer = smart_decode(self.stream.readline()[:-1])
  File "/usr/lib/python3.10/socket.py", line 705, in readinto
    return self._sock.recv_into(b)
  File "/home/april/spark-3.5.1-bin-hadoop3/python/lib/pyspark.zip/pyspark/context.py", line 381, in signal_handler
    self.cancelAllJobs()
  File "/home/april/spark-3.5.1-bin-hadoop3/python/lib/pyspark.zip/pyspark/context.py", line 2446, in cancelAllJobs
    self._jsc.sc().cancelAllJobs()
  File "/home/april/spark-3.5.1-bin-hadoop3/python/lib/py4j-0.10.9.7-src.zip/py4j/java_gateway.py", line 1322, in __call__
    return_value = get_return_value(
  File "/home/april/spark-3.5.1-bin-hadoop3/python/lib/pyspark.zip/pyspark/errors/exceptions/captured.py", line 179, in deco
    return f(*a, **kw)
  File "/home/april/spark-3.5.1-bin-hadoop3/python/lib/py4j-0.10.9.7-src.zip/py4j/protocol.py", line 334, in get_return_value
    raise Py4JError(
py4j.protocol.Py4JError: An error occurred while calling o12.sc
2024-06-02 15:53:12,274 Closing down clientserver connection
2024-06-02 15:53:12,274 Exception while sending command.
Traceback (most recent call last):
  File "/home/april/spark-3.5.1-bin-hadoop3/python/lib/py4j-0.10.9.7-src.zip/py4j/clientserver.py", line 511, in send_command
    answer = smart_decode(self.stream.readline()[:-1])
  File "/usr/lib/python3.10/socket.py", line 705, in readinto
    return self._sock.recv_into(b)
  File "/home/april/spark-3.5.1-bin-hadoop3/python/lib/pyspark.zip/pyspark/context.py", line 381, in signal_handler
    self.cancelAllJobs()
  File "/home/april/spark-3.5.1-bin-hadoop3/python/lib/pyspark.zip/pyspark/context.py", line 2446, in cancelAllJobs
    self._jsc.sc().cancelAllJobs()
  File "/home/april/spark-3.5.1-bin-hadoop3/python/lib/py4j-0.10.9.7-src.zip/py4j/java_gateway.py", line 1322, in __call__
    return_value = get_return_value(
  File "/home/april/spark-3.5.1-bin-hadoop3/python/lib/pyspark.zip/pyspark/errors/exceptions/captured.py", line 179, in deco
    return f(*a, **kw)
  File "/home/april/spark-3.5.1-bin-hadoop3/python/lib/py4j-0.10.9.7-src.zip/py4j/protocol.py", line 334, in get_return_value
    raise Py4JError(
py4j.protocol.Py4JError: An error occurred while calling o12.sc

During handling of the above exception, another exception occurred:

Traceback (most recent call last):
  File "/home/april/spark-3.5.1-bin-hadoop3/python/lib/py4j-0.10.9.7-src.zip/py4j/java_gateway.py", line 1038, in send_command
    response = connection.send_command(command)
  File "/home/april/spark-3.5.1-bin-hadoop3/python/lib/py4j-0.10.9.7-src.zip/py4j/clientserver.py", line 539, in send_command
    raise Py4JNetworkError(
py4j.protocol.Py4JNetworkError: Error while sending or receiving
2024-06-02 15:53:12,274 Closing down clientserver connection
2024-06-02 15:53:12,353 Closing down clientserver connection
2024-06-02 15:55:07,293 Closing down clientserver connection
2024-06-02 20:54:17,994 Closing down clientserver connection
2024-06-02 20:55:05,632 Callback Server Starting
2024-06-02 20:55:05,633 Socket listening on ('127.0.0.1', 39831)
2024-06-02 20:55:24,189 Python Server ready to receive messages
2024-06-02 20:55:24,189 Received command c on object id p0
2024-06-02 20:55:57,918 The number of arrivals to Citigroup has doubled from 0 to 10 at 2015-12-01 07:20:00
2024-06-02 20:55:57,919 The number of arrivals to Citigroup has doubled from 0 to 15 at 2015-12-01 07:10:00
2024-06-02 20:55:57,919 The number of arrivals to Citigroup has doubled from 0 to 10 at 2015-12-01 07:50:00
2024-06-02 20:55:57,919 The number of arrivals to Citigroup has doubled from 0 to 10 at 2015-12-01 14:10:00
2024-06-02 20:55:57,919 The number of arrivals to Citigroup has doubled from 0 to 18 at 2015-12-01 07:00:00
2024-06-02 20:55:57,919 The number of arrivals to Citigroup has doubled from 0 to 16 at 2015-12-01 09:10:00
2024-06-02 20:55:57,919 The number of arrivals to Citigroup has doubled from 0 to 11 at 2015-12-01 08:10:00
2024-06-02 20:55:57,920 The number of arrivals to Goldman Sachs has doubled from 0 to 11 at 2015-12-01 09:30:00
2024-06-02 20:55:57,920 The number of arrivals to Citigroup has doubled from 0 to 10 at 2015-12-01 10:00:00
2024-06-02 20:55:57,920 The number of arrivals to Citigroup has doubled from 0 to 12 at 2015-12-01 09:00:00
2024-06-02 20:55:57,920 The number of arrivals to Citigroup has doubled from 0 to 10 at 2015-12-01 07:30:00
2024-06-02 20:55:57,920 The number of arrivals to Goldman Sachs has doubled from 0 to 10 at 2015-12-01 09:40:00
2024-06-02 20:55:57,920 The number of arrivals to Citigroup has doubled from 0 to 12 at 2015-12-01 09:40:00
2024-06-02 20:55:57,921 The number of arrivals to Citigroup has doubled from 0 to 13 at 2015-12-01 06:50:00
2024-06-02 20:55:57,921 The number of arrivals to Citigroup has doubled from 0 to 14 at 2015-12-01 08:30:00
2024-06-02 21:05:05,987 Closing down clientserver connection
2024-06-02 21:06:54,493 Error while receiving.
Traceback (most recent call last):
  File "/home/april/spark-3.5.1-bin-hadoop3/python/lib/py4j-0.10.9.7-src.zip/py4j/clientserver.py", line 511, in send_command
    answer = smart_decode(self.stream.readline()[:-1])
RuntimeError: reentrant call inside <_io.BufferedReader name=4>
2024-06-02 21:06:54,495 Closing down clientserver connection
2024-06-02 21:06:54,495 Exception while sending command.
Traceback (most recent call last):
  File "/home/april/spark-3.5.1-bin-hadoop3/python/lib/py4j-0.10.9.7-src.zip/py4j/clientserver.py", line 511, in send_command
    answer = smart_decode(self.stream.readline()[:-1])
RuntimeError: reentrant call inside <_io.BufferedReader name=4>

During handling of the above exception, another exception occurred:

Traceback (most recent call last):
  File "/home/april/spark-3.5.1-bin-hadoop3/python/lib/py4j-0.10.9.7-src.zip/py4j/java_gateway.py", line 1038, in send_command
    response = connection.send_command(command)
  File "/home/april/spark-3.5.1-bin-hadoop3/python/lib/py4j-0.10.9.7-src.zip/py4j/clientserver.py", line 539, in send_command
    raise Py4JNetworkError(
py4j.protocol.Py4JNetworkError: Error while sending or receiving
2024-06-02 21:06:54,498 Error while receiving.
Traceback (most recent call last):
  File "/home/april/spark-3.5.1-bin-hadoop3/python/lib/py4j-0.10.9.7-src.zip/py4j/clientserver.py", line 511, in send_command
    answer = smart_decode(self.stream.readline()[:-1])
  File "/usr/lib/python3.10/socket.py", line 705, in readinto
    return self._sock.recv_into(b)
  File "/home/april/spark-3.5.1-bin-hadoop3/python/lib/pyspark.zip/pyspark/context.py", line 381, in signal_handler
    self.cancelAllJobs()
  File "/home/april/spark-3.5.1-bin-hadoop3/python/lib/pyspark.zip/pyspark/context.py", line 2446, in cancelAllJobs
    self._jsc.sc().cancelAllJobs()
  File "/home/april/spark-3.5.1-bin-hadoop3/python/lib/py4j-0.10.9.7-src.zip/py4j/java_gateway.py", line 1322, in __call__
    return_value = get_return_value(
  File "/home/april/spark-3.5.1-bin-hadoop3/python/lib/pyspark.zip/pyspark/errors/exceptions/captured.py", line 179, in deco
    return f(*a, **kw)
  File "/home/april/spark-3.5.1-bin-hadoop3/python/lib/py4j-0.10.9.7-src.zip/py4j/protocol.py", line 334, in get_return_value
    raise Py4JError(
py4j.protocol.Py4JError: An error occurred while calling o12.sc
2024-06-02 21:06:54,500 Closing down clientserver connection
2024-06-02 21:06:54,500 Exception while sending command.
Traceback (most recent call last):
  File "/home/april/spark-3.5.1-bin-hadoop3/python/lib/py4j-0.10.9.7-src.zip/py4j/clientserver.py", line 511, in send_command
    answer = smart_decode(self.stream.readline()[:-1])
  File "/usr/lib/python3.10/socket.py", line 705, in readinto
    return self._sock.recv_into(b)
  File "/home/april/spark-3.5.1-bin-hadoop3/python/lib/pyspark.zip/pyspark/context.py", line 381, in signal_handler
    self.cancelAllJobs()
  File "/home/april/spark-3.5.1-bin-hadoop3/python/lib/pyspark.zip/pyspark/context.py", line 2446, in cancelAllJobs
    self._jsc.sc().cancelAllJobs()
  File "/home/april/spark-3.5.1-bin-hadoop3/python/lib/py4j-0.10.9.7-src.zip/py4j/java_gateway.py", line 1322, in __call__
    return_value = get_return_value(
  File "/home/april/spark-3.5.1-bin-hadoop3/python/lib/pyspark.zip/pyspark/errors/exceptions/captured.py", line 179, in deco
    return f(*a, **kw)
  File "/home/april/spark-3.5.1-bin-hadoop3/python/lib/py4j-0.10.9.7-src.zip/py4j/protocol.py", line 334, in get_return_value
    raise Py4JError(
py4j.protocol.Py4JError: An error occurred while calling o12.sc

During handling of the above exception, another exception occurred:

Traceback (most recent call last):
  File "/home/april/spark-3.5.1-bin-hadoop3/python/lib/py4j-0.10.9.7-src.zip/py4j/java_gateway.py", line 1038, in send_command
    response = connection.send_command(command)
  File "/home/april/spark-3.5.1-bin-hadoop3/python/lib/py4j-0.10.9.7-src.zip/py4j/clientserver.py", line 539, in send_command
    raise Py4JNetworkError(
py4j.protocol.Py4JNetworkError: Error while sending or receiving
2024-06-02 21:06:54,501 Closing down clientserver connection
2024-06-02 21:06:54,580 Closing down clientserver connection
2024-06-02 21:08:46,824 Error while receiving.
Traceback (most recent call last):
  File "/home/april/spark-3.5.1-bin-hadoop3/python/lib/py4j-0.10.9.7-src.zip/py4j/clientserver.py", line 511, in send_command
    answer = smart_decode(self.stream.readline()[:-1])
RuntimeError: reentrant call inside <_io.BufferedReader name=4>
2024-06-02 21:08:46,825 Closing down clientserver connection
2024-06-02 21:08:46,825 Exception while sending command.
Traceback (most recent call last):
  File "/home/april/spark-3.5.1-bin-hadoop3/python/lib/py4j-0.10.9.7-src.zip/py4j/clientserver.py", line 511, in send_command
    answer = smart_decode(self.stream.readline()[:-1])
RuntimeError: reentrant call inside <_io.BufferedReader name=4>

During handling of the above exception, another exception occurred:

Traceback (most recent call last):
  File "/home/april/spark-3.5.1-bin-hadoop3/python/lib/py4j-0.10.9.7-src.zip/py4j/java_gateway.py", line 1038, in send_command
    response = connection.send_command(command)
  File "/home/april/spark-3.5.1-bin-hadoop3/python/lib/py4j-0.10.9.7-src.zip/py4j/clientserver.py", line 539, in send_command
    raise Py4JNetworkError(
py4j.protocol.Py4JNetworkError: Error while sending or receiving
2024-06-02 21:08:46,826 Error while receiving.
Traceback (most recent call last):
  File "/home/april/spark-3.5.1-bin-hadoop3/python/lib/py4j-0.10.9.7-src.zip/py4j/clientserver.py", line 511, in send_command
    answer = smart_decode(self.stream.readline()[:-1])
  File "/usr/lib/python3.10/socket.py", line 705, in readinto
    return self._sock.recv_into(b)
  File "/home/april/spark-3.5.1-bin-hadoop3/python/lib/pyspark.zip/pyspark/context.py", line 381, in signal_handler
    self.cancelAllJobs()
  File "/home/april/spark-3.5.1-bin-hadoop3/python/lib/pyspark.zip/pyspark/context.py", line 2446, in cancelAllJobs
    self._jsc.sc().cancelAllJobs()
  File "/home/april/spark-3.5.1-bin-hadoop3/python/lib/py4j-0.10.9.7-src.zip/py4j/java_gateway.py", line 1322, in __call__
    return_value = get_return_value(
  File "/home/april/spark-3.5.1-bin-hadoop3/python/lib/pyspark.zip/pyspark/errors/exceptions/captured.py", line 179, in deco
    return f(*a, **kw)
  File "/home/april/spark-3.5.1-bin-hadoop3/python/lib/py4j-0.10.9.7-src.zip/py4j/protocol.py", line 334, in get_return_value
    raise Py4JError(
py4j.protocol.Py4JError: An error occurred while calling o12.sc
2024-06-02 21:08:46,827 Closing down clientserver connection
2024-06-02 21:08:46,827 Exception while sending command.
Traceback (most recent call last):
  File "/home/april/spark-3.5.1-bin-hadoop3/python/lib/py4j-0.10.9.7-src.zip/py4j/clientserver.py", line 511, in send_command
    answer = smart_decode(self.stream.readline()[:-1])
  File "/usr/lib/python3.10/socket.py", line 705, in readinto
    return self._sock.recv_into(b)
  File "/home/april/spark-3.5.1-bin-hadoop3/python/lib/pyspark.zip/pyspark/context.py", line 381, in signal_handler
    self.cancelAllJobs()
  File "/home/april/spark-3.5.1-bin-hadoop3/python/lib/pyspark.zip/pyspark/context.py", line 2446, in cancelAllJobs
    self._jsc.sc().cancelAllJobs()
  File "/home/april/spark-3.5.1-bin-hadoop3/python/lib/py4j-0.10.9.7-src.zip/py4j/java_gateway.py", line 1322, in __call__
    return_value = get_return_value(
  File "/home/april/spark-3.5.1-bin-hadoop3/python/lib/pyspark.zip/pyspark/errors/exceptions/captured.py", line 179, in deco
    return f(*a, **kw)
  File "/home/april/spark-3.5.1-bin-hadoop3/python/lib/py4j-0.10.9.7-src.zip/py4j/protocol.py", line 334, in get_return_value
    raise Py4JError(
py4j.protocol.Py4JError: An error occurred while calling o12.sc

During handling of the above exception, another exception occurred:

Traceback (most recent call last):
  File "/home/april/spark-3.5.1-bin-hadoop3/python/lib/py4j-0.10.9.7-src.zip/py4j/java_gateway.py", line 1038, in send_command
    response = connection.send_command(command)
  File "/home/april/spark-3.5.1-bin-hadoop3/python/lib/py4j-0.10.9.7-src.zip/py4j/clientserver.py", line 539, in send_command
    raise Py4JNetworkError(
py4j.protocol.Py4JNetworkError: Error while sending or receiving
2024-06-02 21:08:46,827 Closing down clientserver connection
2024-06-02 21:08:46,911 Closing down clientserver connection
2024-06-02 21:16:45,007 Error while receiving.
Traceback (most recent call last):
  File "/home/april/spark-3.5.1-bin-hadoop3/python/lib/py4j-0.10.9.7-src.zip/py4j/clientserver.py", line 511, in send_command
    answer = smart_decode(self.stream.readline()[:-1])
RuntimeError: reentrant call inside <_io.BufferedReader name=4>
2024-06-02 21:16:45,008 Closing down clientserver connection
2024-06-02 21:16:45,008 Exception while sending command.
Traceback (most recent call last):
  File "/home/april/spark-3.5.1-bin-hadoop3/python/lib/py4j-0.10.9.7-src.zip/py4j/clientserver.py", line 511, in send_command
    answer = smart_decode(self.stream.readline()[:-1])
RuntimeError: reentrant call inside <_io.BufferedReader name=4>

During handling of the above exception, another exception occurred:

Traceback (most recent call last):
  File "/home/april/spark-3.5.1-bin-hadoop3/python/lib/py4j-0.10.9.7-src.zip/py4j/java_gateway.py", line 1038, in send_command
    response = connection.send_command(command)
  File "/home/april/spark-3.5.1-bin-hadoop3/python/lib/py4j-0.10.9.7-src.zip/py4j/clientserver.py", line 539, in send_command
    raise Py4JNetworkError(
py4j.protocol.Py4JNetworkError: Error while sending or receiving
2024-06-02 21:16:45,009 Error while receiving.
Traceback (most recent call last):
  File "/home/april/spark-3.5.1-bin-hadoop3/python/lib/py4j-0.10.9.7-src.zip/py4j/clientserver.py", line 511, in send_command
    answer = smart_decode(self.stream.readline()[:-1])
  File "/usr/lib/python3.10/socket.py", line 705, in readinto
    return self._sock.recv_into(b)
  File "/home/april/spark-3.5.1-bin-hadoop3/python/lib/pyspark.zip/pyspark/context.py", line 381, in signal_handler
    self.cancelAllJobs()
  File "/home/april/spark-3.5.1-bin-hadoop3/python/lib/pyspark.zip/pyspark/context.py", line 2446, in cancelAllJobs
    self._jsc.sc().cancelAllJobs()
  File "/home/april/spark-3.5.1-bin-hadoop3/python/lib/py4j-0.10.9.7-src.zip/py4j/java_gateway.py", line 1322, in __call__
    return_value = get_return_value(
  File "/home/april/spark-3.5.1-bin-hadoop3/python/lib/pyspark.zip/pyspark/errors/exceptions/captured.py", line 179, in deco
    return f(*a, **kw)
  File "/home/april/spark-3.5.1-bin-hadoop3/python/lib/py4j-0.10.9.7-src.zip/py4j/protocol.py", line 334, in get_return_value
    raise Py4JError(
py4j.protocol.Py4JError: An error occurred while calling o12.sc
2024-06-02 21:16:45,010 Closing down clientserver connection
2024-06-02 21:16:45,010 Exception while sending command.
Traceback (most recent call last):
  File "/home/april/spark-3.5.1-bin-hadoop3/python/lib/py4j-0.10.9.7-src.zip/py4j/clientserver.py", line 511, in send_command
    answer = smart_decode(self.stream.readline()[:-1])
  File "/usr/lib/python3.10/socket.py", line 705, in readinto
    return self._sock.recv_into(b)
  File "/home/april/spark-3.5.1-bin-hadoop3/python/lib/pyspark.zip/pyspark/context.py", line 381, in signal_handler
    self.cancelAllJobs()
  File "/home/april/spark-3.5.1-bin-hadoop3/python/lib/pyspark.zip/pyspark/context.py", line 2446, in cancelAllJobs
    self._jsc.sc().cancelAllJobs()
  File "/home/april/spark-3.5.1-bin-hadoop3/python/lib/py4j-0.10.9.7-src.zip/py4j/java_gateway.py", line 1322, in __call__
    return_value = get_return_value(
  File "/home/april/spark-3.5.1-bin-hadoop3/python/lib/pyspark.zip/pyspark/errors/exceptions/captured.py", line 179, in deco
    return f(*a, **kw)
  File "/home/april/spark-3.5.1-bin-hadoop3/python/lib/py4j-0.10.9.7-src.zip/py4j/protocol.py", line 334, in get_return_value
    raise Py4JError(
py4j.protocol.Py4JError: An error occurred while calling o12.sc

During handling of the above exception, another exception occurred:

Traceback (most recent call last):
  File "/home/april/spark-3.5.1-bin-hadoop3/python/lib/py4j-0.10.9.7-src.zip/py4j/java_gateway.py", line 1038, in send_command
    response = connection.send_command(command)
  File "/home/april/spark-3.5.1-bin-hadoop3/python/lib/py4j-0.10.9.7-src.zip/py4j/clientserver.py", line 539, in send_command
    raise Py4JNetworkError(
py4j.protocol.Py4JNetworkError: Error while sending or receiving
2024-06-02 21:16:45,010 Closing down clientserver connection
2024-06-02 21:16:45,087 Closing down clientserver connection
2024-06-02 21:18:13,575 Error while receiving.
Traceback (most recent call last):
  File "/home/april/spark-3.5.1-bin-hadoop3/python/lib/py4j-0.10.9.7-src.zip/py4j/clientserver.py", line 511, in send_command
    answer = smart_decode(self.stream.readline()[:-1])
RuntimeError: reentrant call inside <_io.BufferedReader name=4>
2024-06-02 21:18:13,577 Closing down clientserver connection
2024-06-02 21:18:13,577 Exception while sending command.
Traceback (most recent call last):
  File "/home/april/spark-3.5.1-bin-hadoop3/python/lib/py4j-0.10.9.7-src.zip/py4j/clientserver.py", line 511, in send_command
    answer = smart_decode(self.stream.readline()[:-1])
RuntimeError: reentrant call inside <_io.BufferedReader name=4>

During handling of the above exception, another exception occurred:

Traceback (most recent call last):
  File "/home/april/spark-3.5.1-bin-hadoop3/python/lib/py4j-0.10.9.7-src.zip/py4j/java_gateway.py", line 1038, in send_command
    response = connection.send_command(command)
  File "/home/april/spark-3.5.1-bin-hadoop3/python/lib/py4j-0.10.9.7-src.zip/py4j/clientserver.py", line 539, in send_command
    raise Py4JNetworkError(
py4j.protocol.Py4JNetworkError: Error while sending or receiving
2024-06-02 21:18:13,579 Error while receiving.
Traceback (most recent call last):
  File "/home/april/spark-3.5.1-bin-hadoop3/python/lib/py4j-0.10.9.7-src.zip/py4j/clientserver.py", line 511, in send_command
    answer = smart_decode(self.stream.readline()[:-1])
  File "/usr/lib/python3.10/socket.py", line 705, in readinto
    return self._sock.recv_into(b)
  File "/home/april/spark-3.5.1-bin-hadoop3/python/lib/pyspark.zip/pyspark/context.py", line 381, in signal_handler
    self.cancelAllJobs()
  File "/home/april/spark-3.5.1-bin-hadoop3/python/lib/pyspark.zip/pyspark/context.py", line 2446, in cancelAllJobs
    self._jsc.sc().cancelAllJobs()
  File "/home/april/spark-3.5.1-bin-hadoop3/python/lib/py4j-0.10.9.7-src.zip/py4j/java_gateway.py", line 1322, in __call__
    return_value = get_return_value(
  File "/home/april/spark-3.5.1-bin-hadoop3/python/lib/pyspark.zip/pyspark/errors/exceptions/captured.py", line 179, in deco
    return f(*a, **kw)
  File "/home/april/spark-3.5.1-bin-hadoop3/python/lib/py4j-0.10.9.7-src.zip/py4j/protocol.py", line 334, in get_return_value
    raise Py4JError(
py4j.protocol.Py4JError: An error occurred while calling o12.sc
2024-06-02 21:18:13,581 Closing down clientserver connection
2024-06-02 21:18:13,581 Exception while sending command.
Traceback (most recent call last):
  File "/home/april/spark-3.5.1-bin-hadoop3/python/lib/py4j-0.10.9.7-src.zip/py4j/clientserver.py", line 511, in send_command
    answer = smart_decode(self.stream.readline()[:-1])
  File "/usr/lib/python3.10/socket.py", line 705, in readinto
    return self._sock.recv_into(b)
  File "/home/april/spark-3.5.1-bin-hadoop3/python/lib/pyspark.zip/pyspark/context.py", line 381, in signal_handler
    self.cancelAllJobs()
  File "/home/april/spark-3.5.1-bin-hadoop3/python/lib/pyspark.zip/pyspark/context.py", line 2446, in cancelAllJobs
    self._jsc.sc().cancelAllJobs()
  File "/home/april/spark-3.5.1-bin-hadoop3/python/lib/py4j-0.10.9.7-src.zip/py4j/java_gateway.py", line 1322, in __call__
    return_value = get_return_value(
  File "/home/april/spark-3.5.1-bin-hadoop3/python/lib/pyspark.zip/pyspark/errors/exceptions/captured.py", line 179, in deco
    return f(*a, **kw)
  File "/home/april/spark-3.5.1-bin-hadoop3/python/lib/py4j-0.10.9.7-src.zip/py4j/protocol.py", line 334, in get_return_value
    raise Py4JError(
py4j.protocol.Py4JError: An error occurred while calling o12.sc

During handling of the above exception, another exception occurred:

Traceback (most recent call last):
  File "/home/april/spark-3.5.1-bin-hadoop3/python/lib/py4j-0.10.9.7-src.zip/py4j/java_gateway.py", line 1038, in send_command
    response = connection.send_command(command)
  File "/home/april/spark-3.5.1-bin-hadoop3/python/lib/py4j-0.10.9.7-src.zip/py4j/clientserver.py", line 539, in send_command
    raise Py4JNetworkError(
py4j.protocol.Py4JNetworkError: Error while sending or receiving
2024-06-02 21:18:13,581 Closing down clientserver connection
2024-06-02 21:18:13,674 Closing down clientserver connection
2024-06-02 21:21:44,811 Error while receiving.
Traceback (most recent call last):
  File "/home/april/spark-3.5.1-bin-hadoop3/python/lib/py4j-0.10.9.7-src.zip/py4j/clientserver.py", line 511, in send_command
    answer = smart_decode(self.stream.readline()[:-1])
RuntimeError: reentrant call inside <_io.BufferedReader name=4>
2024-06-02 21:21:44,812 Closing down clientserver connection
2024-06-02 21:21:44,812 Exception while sending command.
Traceback (most recent call last):
  File "/home/april/spark-3.5.1-bin-hadoop3/python/lib/py4j-0.10.9.7-src.zip/py4j/clientserver.py", line 511, in send_command
    answer = smart_decode(self.stream.readline()[:-1])
RuntimeError: reentrant call inside <_io.BufferedReader name=4>

During handling of the above exception, another exception occurred:

Traceback (most recent call last):
  File "/home/april/spark-3.5.1-bin-hadoop3/python/lib/py4j-0.10.9.7-src.zip/py4j/java_gateway.py", line 1038, in send_command
    response = connection.send_command(command)
  File "/home/april/spark-3.5.1-bin-hadoop3/python/lib/py4j-0.10.9.7-src.zip/py4j/clientserver.py", line 539, in send_command
    raise Py4JNetworkError(
py4j.protocol.Py4JNetworkError: Error while sending or receiving
2024-06-02 21:21:44,813 Error while receiving.
Traceback (most recent call last):
  File "/home/april/spark-3.5.1-bin-hadoop3/python/lib/py4j-0.10.9.7-src.zip/py4j/clientserver.py", line 511, in send_command
    answer = smart_decode(self.stream.readline()[:-1])
  File "/usr/lib/python3.10/socket.py", line 705, in readinto
    return self._sock.recv_into(b)
  File "/home/april/spark-3.5.1-bin-hadoop3/python/lib/pyspark.zip/pyspark/context.py", line 381, in signal_handler
    self.cancelAllJobs()
  File "/home/april/spark-3.5.1-bin-hadoop3/python/lib/pyspark.zip/pyspark/context.py", line 2446, in cancelAllJobs
    self._jsc.sc().cancelAllJobs()
  File "/home/april/spark-3.5.1-bin-hadoop3/python/lib/py4j-0.10.9.7-src.zip/py4j/java_gateway.py", line 1322, in __call__
    return_value = get_return_value(
  File "/home/april/spark-3.5.1-bin-hadoop3/python/lib/pyspark.zip/pyspark/errors/exceptions/captured.py", line 179, in deco
    return f(*a, **kw)
  File "/home/april/spark-3.5.1-bin-hadoop3/python/lib/py4j-0.10.9.7-src.zip/py4j/protocol.py", line 334, in get_return_value
    raise Py4JError(
py4j.protocol.Py4JError: An error occurred while calling o12.sc
2024-06-02 21:21:44,814 Closing down clientserver connection
2024-06-02 21:21:44,814 Exception while sending command.
Traceback (most recent call last):
  File "/home/april/spark-3.5.1-bin-hadoop3/python/lib/py4j-0.10.9.7-src.zip/py4j/clientserver.py", line 511, in send_command
    answer = smart_decode(self.stream.readline()[:-1])
  File "/usr/lib/python3.10/socket.py", line 705, in readinto
    return self._sock.recv_into(b)
  File "/home/april/spark-3.5.1-bin-hadoop3/python/lib/pyspark.zip/pyspark/context.py", line 381, in signal_handler
    self.cancelAllJobs()
  File "/home/april/spark-3.5.1-bin-hadoop3/python/lib/pyspark.zip/pyspark/context.py", line 2446, in cancelAllJobs
    self._jsc.sc().cancelAllJobs()
  File "/home/april/spark-3.5.1-bin-hadoop3/python/lib/py4j-0.10.9.7-src.zip/py4j/java_gateway.py", line 1322, in __call__
    return_value = get_return_value(
  File "/home/april/spark-3.5.1-bin-hadoop3/python/lib/pyspark.zip/pyspark/errors/exceptions/captured.py", line 179, in deco
    return f(*a, **kw)
  File "/home/april/spark-3.5.1-bin-hadoop3/python/lib/py4j-0.10.9.7-src.zip/py4j/protocol.py", line 334, in get_return_value
    raise Py4JError(
py4j.protocol.Py4JError: An error occurred while calling o12.sc

During handling of the above exception, another exception occurred:

Traceback (most recent call last):
  File "/home/april/spark-3.5.1-bin-hadoop3/python/lib/py4j-0.10.9.7-src.zip/py4j/java_gateway.py", line 1038, in send_command
    response = connection.send_command(command)
  File "/home/april/spark-3.5.1-bin-hadoop3/python/lib/py4j-0.10.9.7-src.zip/py4j/clientserver.py", line 539, in send_command
    raise Py4JNetworkError(
py4j.protocol.Py4JNetworkError: Error while sending or receiving
2024-06-02 21:21:44,815 Closing down clientserver connection
2024-06-02 21:21:44,891 Closing down clientserver connection
2024-06-02 21:21:56,840 Callback Server Starting
2024-06-02 21:21:56,840 Socket listening on ('127.0.0.1', 46325)
2024-06-02 21:22:45,833 Python Server ready to receive messages
2024-06-02 21:22:45,834 Received command c on object id p0
2024-06-02 21:31:57,179 Closing down clientserver connection
2024-06-04 23:47:05,413 Error while receiving.
Traceback (most recent call last):
  File "/home/april/spark-3.5.1-bin-hadoop3/python/lib/py4j-0.10.9.7-src.zip/py4j/clientserver.py", line 511, in send_command
    answer = smart_decode(self.stream.readline()[:-1])
RuntimeError: reentrant call inside <_io.BufferedReader name=4>
2024-06-04 23:47:05,415 Closing down clientserver connection
2024-06-04 23:47:05,415 Exception while sending command.
Traceback (most recent call last):
  File "/home/april/spark-3.5.1-bin-hadoop3/python/lib/py4j-0.10.9.7-src.zip/py4j/clientserver.py", line 511, in send_command
    answer = smart_decode(self.stream.readline()[:-1])
RuntimeError: reentrant call inside <_io.BufferedReader name=4>

During handling of the above exception, another exception occurred:

Traceback (most recent call last):
  File "/home/april/spark-3.5.1-bin-hadoop3/python/lib/py4j-0.10.9.7-src.zip/py4j/java_gateway.py", line 1038, in send_command
    response = connection.send_command(command)
  File "/home/april/spark-3.5.1-bin-hadoop3/python/lib/py4j-0.10.9.7-src.zip/py4j/clientserver.py", line 539, in send_command
    raise Py4JNetworkError(
py4j.protocol.Py4JNetworkError: Error while sending or receiving
2024-06-04 23:47:05,418 Error while receiving.
Traceback (most recent call last):
  File "/home/april/spark-3.5.1-bin-hadoop3/python/lib/py4j-0.10.9.7-src.zip/py4j/clientserver.py", line 511, in send_command
    answer = smart_decode(self.stream.readline()[:-1])
  File "/usr/lib/python3.10/socket.py", line 705, in readinto
    return self._sock.recv_into(b)
  File "/home/april/spark-3.5.1-bin-hadoop3/python/lib/pyspark.zip/pyspark/context.py", line 381, in signal_handler
    self.cancelAllJobs()
  File "/home/april/spark-3.5.1-bin-hadoop3/python/lib/pyspark.zip/pyspark/context.py", line 2446, in cancelAllJobs
    self._jsc.sc().cancelAllJobs()
  File "/home/april/spark-3.5.1-bin-hadoop3/python/lib/py4j-0.10.9.7-src.zip/py4j/java_gateway.py", line 1322, in __call__
    return_value = get_return_value(
  File "/home/april/spark-3.5.1-bin-hadoop3/python/lib/pyspark.zip/pyspark/errors/exceptions/captured.py", line 179, in deco
    return f(*a, **kw)
  File "/home/april/spark-3.5.1-bin-hadoop3/python/lib/py4j-0.10.9.7-src.zip/py4j/protocol.py", line 334, in get_return_value
    raise Py4JError(
py4j.protocol.Py4JError: An error occurred while calling o12.sc
2024-06-04 23:47:05,421 Closing down clientserver connection
2024-06-04 23:47:05,421 Exception while sending command.
Traceback (most recent call last):
  File "/home/april/spark-3.5.1-bin-hadoop3/python/lib/py4j-0.10.9.7-src.zip/py4j/clientserver.py", line 511, in send_command
    answer = smart_decode(self.stream.readline()[:-1])
  File "/usr/lib/python3.10/socket.py", line 705, in readinto
    return self._sock.recv_into(b)
  File "/home/april/spark-3.5.1-bin-hadoop3/python/lib/pyspark.zip/pyspark/context.py", line 381, in signal_handler
    self.cancelAllJobs()
  File "/home/april/spark-3.5.1-bin-hadoop3/python/lib/pyspark.zip/pyspark/context.py", line 2446, in cancelAllJobs
    self._jsc.sc().cancelAllJobs()
  File "/home/april/spark-3.5.1-bin-hadoop3/python/lib/py4j-0.10.9.7-src.zip/py4j/java_gateway.py", line 1322, in __call__
    return_value = get_return_value(
  File "/home/april/spark-3.5.1-bin-hadoop3/python/lib/pyspark.zip/pyspark/errors/exceptions/captured.py", line 179, in deco
    return f(*a, **kw)
  File "/home/april/spark-3.5.1-bin-hadoop3/python/lib/py4j-0.10.9.7-src.zip/py4j/protocol.py", line 334, in get_return_value
    raise Py4JError(
py4j.protocol.Py4JError: An error occurred while calling o12.sc

During handling of the above exception, another exception occurred:

Traceback (most recent call last):
  File "/home/april/spark-3.5.1-bin-hadoop3/python/lib/py4j-0.10.9.7-src.zip/py4j/java_gateway.py", line 1038, in send_command
    response = connection.send_command(command)
  File "/home/april/spark-3.5.1-bin-hadoop3/python/lib/py4j-0.10.9.7-src.zip/py4j/clientserver.py", line 539, in send_command
    raise Py4JNetworkError(
py4j.protocol.Py4JNetworkError: Error while sending or receiving
2024-06-04 23:47:05,421 Closing down clientserver connection
2024-06-04 23:47:05,485 Closing down clientserver connection
2024-06-04 23:47:13,151 Closing down clientserver connection
2024-06-04 23:48:54,268 Callback Server Starting
2024-06-04 23:48:54,268 Socket listening on ('127.0.0.1', 34531)
2024-06-04 23:48:54,460 Closing down clientserver connection
2024-06-04 23:50:43,200 Closing down clientserver connection
2024-06-04 23:51:21,066 Callback Server Starting
2024-06-04 23:51:21,067 Socket listening on ('127.0.0.1', 39735)
2024-06-04 23:51:52,232 Python Server ready to receive messages
2024-06-04 23:51:52,232 Received command c on object id p0
2024-06-04 23:52:23,637 Error while receiving.
Traceback (most recent call last):
  File "/home/april/spark-3.5.1-bin-hadoop3/python/lib/py4j-0.10.9.7-src.zip/py4j/clientserver.py", line 511, in send_command
    answer = smart_decode(self.stream.readline()[:-1])
RuntimeError: reentrant call inside <_io.BufferedReader name=4>
2024-06-04 23:52:23,637 Closing down clientserver connection
2024-06-04 23:52:23,638 Exception while sending command.
Traceback (most recent call last):
  File "/home/april/spark-3.5.1-bin-hadoop3/python/lib/py4j-0.10.9.7-src.zip/py4j/clientserver.py", line 511, in send_command
    answer = smart_decode(self.stream.readline()[:-1])
RuntimeError: reentrant call inside <_io.BufferedReader name=4>

During handling of the above exception, another exception occurred:

Traceback (most recent call last):
  File "/home/april/spark-3.5.1-bin-hadoop3/python/lib/py4j-0.10.9.7-src.zip/py4j/java_gateway.py", line 1038, in send_command
    response = connection.send_command(command)
  File "/home/april/spark-3.5.1-bin-hadoop3/python/lib/py4j-0.10.9.7-src.zip/py4j/clientserver.py", line 539, in send_command
    raise Py4JNetworkError(
py4j.protocol.Py4JNetworkError: Error while sending or receiving
2024-06-04 23:52:23,640 Error while receiving.
Traceback (most recent call last):
  File "/home/april/spark-3.5.1-bin-hadoop3/python/lib/py4j-0.10.9.7-src.zip/py4j/clientserver.py", line 511, in send_command
    answer = smart_decode(self.stream.readline()[:-1])
  File "/usr/lib/python3.10/socket.py", line 705, in readinto
    return self._sock.recv_into(b)
  File "/home/april/spark-3.5.1-bin-hadoop3/python/lib/pyspark.zip/pyspark/context.py", line 381, in signal_handler
    self.cancelAllJobs()
  File "/home/april/spark-3.5.1-bin-hadoop3/python/lib/pyspark.zip/pyspark/context.py", line 2446, in cancelAllJobs
    self._jsc.sc().cancelAllJobs()
  File "/home/april/spark-3.5.1-bin-hadoop3/python/lib/py4j-0.10.9.7-src.zip/py4j/java_gateway.py", line 1322, in __call__
    return_value = get_return_value(
  File "/home/april/spark-3.5.1-bin-hadoop3/python/lib/pyspark.zip/pyspark/errors/exceptions/captured.py", line 179, in deco
    return f(*a, **kw)
  File "/home/april/spark-3.5.1-bin-hadoop3/python/lib/py4j-0.10.9.7-src.zip/py4j/protocol.py", line 334, in get_return_value
    raise Py4JError(
py4j.protocol.Py4JError: An error occurred while calling o12.sc
2024-06-04 23:52:23,642 Closing down clientserver connection
2024-06-04 23:52:23,642 Exception while sending command.
Traceback (most recent call last):
  File "/home/april/spark-3.5.1-bin-hadoop3/python/lib/py4j-0.10.9.7-src.zip/py4j/clientserver.py", line 511, in send_command
    answer = smart_decode(self.stream.readline()[:-1])
  File "/usr/lib/python3.10/socket.py", line 705, in readinto
    return self._sock.recv_into(b)
  File "/home/april/spark-3.5.1-bin-hadoop3/python/lib/pyspark.zip/pyspark/context.py", line 381, in signal_handler
    self.cancelAllJobs()
  File "/home/april/spark-3.5.1-bin-hadoop3/python/lib/pyspark.zip/pyspark/context.py", line 2446, in cancelAllJobs
    self._jsc.sc().cancelAllJobs()
  File "/home/april/spark-3.5.1-bin-hadoop3/python/lib/py4j-0.10.9.7-src.zip/py4j/java_gateway.py", line 1322, in __call__
    return_value = get_return_value(
  File "/home/april/spark-3.5.1-bin-hadoop3/python/lib/pyspark.zip/pyspark/errors/exceptions/captured.py", line 179, in deco
    return f(*a, **kw)
  File "/home/april/spark-3.5.1-bin-hadoop3/python/lib/py4j-0.10.9.7-src.zip/py4j/protocol.py", line 334, in get_return_value
    raise Py4JError(
py4j.protocol.Py4JError: An error occurred while calling o12.sc

During handling of the above exception, another exception occurred:

Traceback (most recent call last):
  File "/home/april/spark-3.5.1-bin-hadoop3/python/lib/py4j-0.10.9.7-src.zip/py4j/java_gateway.py", line 1038, in send_command
    response = connection.send_command(command)
  File "/home/april/spark-3.5.1-bin-hadoop3/python/lib/py4j-0.10.9.7-src.zip/py4j/clientserver.py", line 539, in send_command
    raise Py4JNetworkError(
py4j.protocol.Py4JNetworkError: Error while sending or receiving
2024-06-04 23:52:23,642 Closing down clientserver connection
2024-06-04 23:52:23,719 Closing down clientserver connection
2024-06-04 23:52:31,522 Callback Server Starting
2024-06-04 23:52:31,522 Socket listening on ('127.0.0.1', 45433)
2024-06-04 23:53:04,808 Python Server ready to receive messages
2024-06-04 23:53:04,809 Received command c on object id p0
2024-06-04 23:54:08,005 Error while receiving.
Traceback (most recent call last):
  File "/home/april/spark-3.5.1-bin-hadoop3/python/lib/py4j-0.10.9.7-src.zip/py4j/clientserver.py", line 511, in send_command
    answer = smart_decode(self.stream.readline()[:-1])
RuntimeError: reentrant call inside <_io.BufferedReader name=4>
2024-06-04 23:54:08,006 Closing down clientserver connection
2024-06-04 23:54:08,006 Exception while sending command.
Traceback (most recent call last):
  File "/home/april/spark-3.5.1-bin-hadoop3/python/lib/py4j-0.10.9.7-src.zip/py4j/clientserver.py", line 511, in send_command
    answer = smart_decode(self.stream.readline()[:-1])
RuntimeError: reentrant call inside <_io.BufferedReader name=4>

During handling of the above exception, another exception occurred:

Traceback (most recent call last):
  File "/home/april/spark-3.5.1-bin-hadoop3/python/lib/py4j-0.10.9.7-src.zip/py4j/java_gateway.py", line 1038, in send_command
    response = connection.send_command(command)
  File "/home/april/spark-3.5.1-bin-hadoop3/python/lib/py4j-0.10.9.7-src.zip/py4j/clientserver.py", line 539, in send_command
    raise Py4JNetworkError(
py4j.protocol.Py4JNetworkError: Error while sending or receiving
2024-06-04 23:54:08,009 Error while receiving.
Traceback (most recent call last):
  File "/home/april/spark-3.5.1-bin-hadoop3/python/lib/py4j-0.10.9.7-src.zip/py4j/clientserver.py", line 511, in send_command
    answer = smart_decode(self.stream.readline()[:-1])
  File "/usr/lib/python3.10/socket.py", line 705, in readinto
    return self._sock.recv_into(b)
  File "/home/april/spark-3.5.1-bin-hadoop3/python/lib/pyspark.zip/pyspark/context.py", line 381, in signal_handler
    self.cancelAllJobs()
  File "/home/april/spark-3.5.1-bin-hadoop3/python/lib/pyspark.zip/pyspark/context.py", line 2446, in cancelAllJobs
    self._jsc.sc().cancelAllJobs()
  File "/home/april/spark-3.5.1-bin-hadoop3/python/lib/py4j-0.10.9.7-src.zip/py4j/java_gateway.py", line 1322, in __call__
    return_value = get_return_value(
  File "/home/april/spark-3.5.1-bin-hadoop3/python/lib/pyspark.zip/pyspark/errors/exceptions/captured.py", line 179, in deco
    return f(*a, **kw)
  File "/home/april/spark-3.5.1-bin-hadoop3/python/lib/py4j-0.10.9.7-src.zip/py4j/protocol.py", line 334, in get_return_value
    raise Py4JError(
py4j.protocol.Py4JError: An error occurred while calling o12.sc
2024-06-04 23:54:08,010 Closing down clientserver connection
2024-06-04 23:54:08,010 Exception while sending command.
Traceback (most recent call last):
  File "/home/april/spark-3.5.1-bin-hadoop3/python/lib/py4j-0.10.9.7-src.zip/py4j/clientserver.py", line 511, in send_command
    answer = smart_decode(self.stream.readline()[:-1])
  File "/usr/lib/python3.10/socket.py", line 705, in readinto
    return self._sock.recv_into(b)
  File "/home/april/spark-3.5.1-bin-hadoop3/python/lib/pyspark.zip/pyspark/context.py", line 381, in signal_handler
    self.cancelAllJobs()
  File "/home/april/spark-3.5.1-bin-hadoop3/python/lib/pyspark.zip/pyspark/context.py", line 2446, in cancelAllJobs
    self._jsc.sc().cancelAllJobs()
  File "/home/april/spark-3.5.1-bin-hadoop3/python/lib/py4j-0.10.9.7-src.zip/py4j/java_gateway.py", line 1322, in __call__
    return_value = get_return_value(
  File "/home/april/spark-3.5.1-bin-hadoop3/python/lib/pyspark.zip/pyspark/errors/exceptions/captured.py", line 179, in deco
    return f(*a, **kw)
  File "/home/april/spark-3.5.1-bin-hadoop3/python/lib/py4j-0.10.9.7-src.zip/py4j/protocol.py", line 334, in get_return_value
    raise Py4JError(
py4j.protocol.Py4JError: An error occurred while calling o12.sc

During handling of the above exception, another exception occurred:

Traceback (most recent call last):
  File "/home/april/spark-3.5.1-bin-hadoop3/python/lib/py4j-0.10.9.7-src.zip/py4j/java_gateway.py", line 1038, in send_command
    response = connection.send_command(command)
  File "/home/april/spark-3.5.1-bin-hadoop3/python/lib/py4j-0.10.9.7-src.zip/py4j/clientserver.py", line 539, in send_command
    raise Py4JNetworkError(
py4j.protocol.Py4JNetworkError: Error while sending or receiving
2024-06-04 23:54:08,010 Closing down clientserver connection
2024-06-04 23:54:08,077 Closing down clientserver connection
2024-06-04 23:54:14,703 Callback Server Starting
2024-06-04 23:54:14,703 Socket listening on ('127.0.0.1', 43289)
2024-06-04 23:54:46,793 Python Server ready to receive messages
2024-06-04 23:54:46,793 Received command c on object id p0
2024-06-04 23:55:25,580 Error while receiving.
Traceback (most recent call last):
  File "/home/april/spark-3.5.1-bin-hadoop3/python/lib/py4j-0.10.9.7-src.zip/py4j/clientserver.py", line 511, in send_command
    answer = smart_decode(self.stream.readline()[:-1])
RuntimeError: reentrant call inside <_io.BufferedReader name=4>
2024-06-04 23:55:25,580 Closing down clientserver connection
2024-06-04 23:55:25,580 Exception while sending command.
Traceback (most recent call last):
  File "/home/april/spark-3.5.1-bin-hadoop3/python/lib/py4j-0.10.9.7-src.zip/py4j/clientserver.py", line 511, in send_command
    answer = smart_decode(self.stream.readline()[:-1])
RuntimeError: reentrant call inside <_io.BufferedReader name=4>

During handling of the above exception, another exception occurred:

Traceback (most recent call last):
  File "/home/april/spark-3.5.1-bin-hadoop3/python/lib/py4j-0.10.9.7-src.zip/py4j/java_gateway.py", line 1038, in send_command
    response = connection.send_command(command)
  File "/home/april/spark-3.5.1-bin-hadoop3/python/lib/py4j-0.10.9.7-src.zip/py4j/clientserver.py", line 539, in send_command
    raise Py4JNetworkError(
py4j.protocol.Py4JNetworkError: Error while sending or receiving
2024-06-04 23:55:25,583 Error while receiving.
Traceback (most recent call last):
  File "/home/april/spark-3.5.1-bin-hadoop3/python/lib/py4j-0.10.9.7-src.zip/py4j/clientserver.py", line 511, in send_command
    answer = smart_decode(self.stream.readline()[:-1])
  File "/usr/lib/python3.10/socket.py", line 705, in readinto
    return self._sock.recv_into(b)
  File "/home/april/spark-3.5.1-bin-hadoop3/python/lib/pyspark.zip/pyspark/context.py", line 381, in signal_handler
    self.cancelAllJobs()
  File "/home/april/spark-3.5.1-bin-hadoop3/python/lib/pyspark.zip/pyspark/context.py", line 2446, in cancelAllJobs
    self._jsc.sc().cancelAllJobs()
  File "/home/april/spark-3.5.1-bin-hadoop3/python/lib/py4j-0.10.9.7-src.zip/py4j/java_gateway.py", line 1322, in __call__
    return_value = get_return_value(
  File "/home/april/spark-3.5.1-bin-hadoop3/python/lib/pyspark.zip/pyspark/errors/exceptions/captured.py", line 179, in deco
    return f(*a, **kw)
  File "/home/april/spark-3.5.1-bin-hadoop3/python/lib/py4j-0.10.9.7-src.zip/py4j/protocol.py", line 334, in get_return_value
    raise Py4JError(
py4j.protocol.Py4JError: An error occurred while calling o12.sc
2024-06-04 23:55:25,584 Closing down clientserver connection
2024-06-04 23:55:25,584 Exception while sending command.
Traceback (most recent call last):
  File "/home/april/spark-3.5.1-bin-hadoop3/python/lib/py4j-0.10.9.7-src.zip/py4j/clientserver.py", line 511, in send_command
    answer = smart_decode(self.stream.readline()[:-1])
  File "/usr/lib/python3.10/socket.py", line 705, in readinto
    return self._sock.recv_into(b)
  File "/home/april/spark-3.5.1-bin-hadoop3/python/lib/pyspark.zip/pyspark/context.py", line 381, in signal_handler
    self.cancelAllJobs()
  File "/home/april/spark-3.5.1-bin-hadoop3/python/lib/pyspark.zip/pyspark/context.py", line 2446, in cancelAllJobs
    self._jsc.sc().cancelAllJobs()
  File "/home/april/spark-3.5.1-bin-hadoop3/python/lib/py4j-0.10.9.7-src.zip/py4j/java_gateway.py", line 1322, in __call__
    return_value = get_return_value(
  File "/home/april/spark-3.5.1-bin-hadoop3/python/lib/pyspark.zip/pyspark/errors/exceptions/captured.py", line 179, in deco
    return f(*a, **kw)
  File "/home/april/spark-3.5.1-bin-hadoop3/python/lib/py4j-0.10.9.7-src.zip/py4j/protocol.py", line 334, in get_return_value
    raise Py4JError(
py4j.protocol.Py4JError: An error occurred while calling o12.sc

During handling of the above exception, another exception occurred:

Traceback (most recent call last):
  File "/home/april/spark-3.5.1-bin-hadoop3/python/lib/py4j-0.10.9.7-src.zip/py4j/java_gateway.py", line 1038, in send_command
    response = connection.send_command(command)
  File "/home/april/spark-3.5.1-bin-hadoop3/python/lib/py4j-0.10.9.7-src.zip/py4j/clientserver.py", line 539, in send_command
    raise Py4JNetworkError(
py4j.protocol.Py4JNetworkError: Error while sending or receiving
2024-06-04 23:55:25,585 Closing down clientserver connection
2024-06-04 23:55:25,660 Closing down clientserver connection
2024-06-04 23:55:32,619 Callback Server Starting
2024-06-04 23:55:32,620 Socket listening on ('127.0.0.1', 45145)
2024-06-04 23:56:04,690 Python Server ready to receive messages
2024-06-04 23:56:04,690 Received command c on object id p0
2024-06-04 23:56:10,097 There was an exception while executing the Python Proxy on the Python Side.
Traceback (most recent call last):
  File "/home/april/spark-3.5.1-bin-hadoop3/python/lib/py4j-0.10.9.7-src.zip/py4j/clientserver.py", line 617, in _call_proxy
    return_value = getattr(self.pool[obj_id], method)(*params)
  File "/home/april/spark-3.5.1-bin-hadoop3/python/lib/pyspark.zip/pyspark/sql/utils.py", line 120, in call
    raise e
  File "/home/april/spark-3.5.1-bin-hadoop3/python/lib/pyspark.zip/pyspark/sql/utils.py", line 117, in call
    self.func(DataFrame(jdf, wrapped_session_jdf), batch_id)
  File "/home/april/BigDataLab03/TrendingArrivals.py", line 128, in detect_spikes
    print(previous_state[window_end])
KeyError: datetime.datetime(2015, 12, 1, 0, 10)
2024-06-04 23:56:10,499 Closing down clientserver connection
2024-06-04 23:56:50,246 Callback Server Starting
2024-06-04 23:56:50,246 Socket listening on ('127.0.0.1', 43509)
2024-06-04 23:57:23,251 Python Server ready to receive messages
2024-06-04 23:57:23,251 Received command c on object id p0
2024-06-04 23:57:28,920 There was an exception while executing the Python Proxy on the Python Side.
Traceback (most recent call last):
  File "/home/april/spark-3.5.1-bin-hadoop3/python/lib/py4j-0.10.9.7-src.zip/py4j/clientserver.py", line 617, in _call_proxy
    return_value = getattr(self.pool[obj_id], method)(*params)
  File "/home/april/spark-3.5.1-bin-hadoop3/python/lib/pyspark.zip/pyspark/sql/utils.py", line 120, in call
    raise e
  File "/home/april/spark-3.5.1-bin-hadoop3/python/lib/pyspark.zip/pyspark/sql/utils.py", line 117, in call
    self.func(DataFrame(jdf, wrapped_session_jdf), batch_id)
  File "/home/april/BigDataLab03/TrendingArrivals.py", line 128, in detect_spikes
    print(previous_state[window_end])
KeyError: datetime.datetime(2015, 12, 1, 0, 10)
2024-06-04 23:57:29,324 Closing down clientserver connection
2024-06-04 23:58:19,539 Callback Server Starting
2024-06-04 23:58:19,539 Socket listening on ('127.0.0.1', 38031)
2024-06-04 23:58:51,153 Python Server ready to receive messages
2024-06-04 23:58:51,153 Received command c on object id p0
2024-06-04 23:58:56,093 There was an exception while executing the Python Proxy on the Python Side.
Traceback (most recent call last):
  File "/home/april/spark-3.5.1-bin-hadoop3/python/lib/py4j-0.10.9.7-src.zip/py4j/clientserver.py", line 617, in _call_proxy
    return_value = getattr(self.pool[obj_id], method)(*params)
  File "/home/april/spark-3.5.1-bin-hadoop3/python/lib/pyspark.zip/pyspark/sql/utils.py", line 120, in call
    raise e
  File "/home/april/spark-3.5.1-bin-hadoop3/python/lib/pyspark.zip/pyspark/sql/utils.py", line 117, in call
    self.func(DataFrame(jdf, wrapped_session_jdf), batch_id)
  File "/home/april/BigDataLab03/TrendingArrivals.py", line 128, in detect_spikes
    print(previous_state[window_end])
KeyError: datetime.datetime(2015, 12, 1, 0, 10)
2024-06-04 23:58:56,433 Closing down clientserver connection
2024-06-04 23:59:28,940 Callback Server Starting
2024-06-04 23:59:28,940 Socket listening on ('127.0.0.1', 39657)
2024-06-04 23:59:57,701 Python Server ready to receive messages
2024-06-04 23:59:57,701 Received command c on object id p0
2024-06-05 00:02:55,657 Error while receiving.
Traceback (most recent call last):
  File "/home/april/spark-3.5.1-bin-hadoop3/python/lib/py4j-0.10.9.7-src.zip/py4j/clientserver.py", line 511, in send_command
    answer = smart_decode(self.stream.readline()[:-1])
RuntimeError: reentrant call inside <_io.BufferedReader name=4>
2024-06-05 00:02:55,658 Closing down clientserver connection
2024-06-05 00:02:55,658 Exception while sending command.
Traceback (most recent call last):
  File "/home/april/spark-3.5.1-bin-hadoop3/python/lib/py4j-0.10.9.7-src.zip/py4j/clientserver.py", line 511, in send_command
    answer = smart_decode(self.stream.readline()[:-1])
RuntimeError: reentrant call inside <_io.BufferedReader name=4>

During handling of the above exception, another exception occurred:

Traceback (most recent call last):
  File "/home/april/spark-3.5.1-bin-hadoop3/python/lib/py4j-0.10.9.7-src.zip/py4j/java_gateway.py", line 1038, in send_command
    response = connection.send_command(command)
  File "/home/april/spark-3.5.1-bin-hadoop3/python/lib/py4j-0.10.9.7-src.zip/py4j/clientserver.py", line 539, in send_command
    raise Py4JNetworkError(
py4j.protocol.Py4JNetworkError: Error while sending or receiving
2024-06-05 00:02:55,660 Error while receiving.
Traceback (most recent call last):
  File "/home/april/spark-3.5.1-bin-hadoop3/python/lib/py4j-0.10.9.7-src.zip/py4j/clientserver.py", line 511, in send_command
    answer = smart_decode(self.stream.readline()[:-1])
  File "/usr/lib/python3.10/socket.py", line 705, in readinto
    return self._sock.recv_into(b)
  File "/home/april/spark-3.5.1-bin-hadoop3/python/lib/pyspark.zip/pyspark/context.py", line 381, in signal_handler
    self.cancelAllJobs()
  File "/home/april/spark-3.5.1-bin-hadoop3/python/lib/pyspark.zip/pyspark/context.py", line 2446, in cancelAllJobs
    self._jsc.sc().cancelAllJobs()
  File "/home/april/spark-3.5.1-bin-hadoop3/python/lib/py4j-0.10.9.7-src.zip/py4j/java_gateway.py", line 1322, in __call__
    return_value = get_return_value(
  File "/home/april/spark-3.5.1-bin-hadoop3/python/lib/pyspark.zip/pyspark/errors/exceptions/captured.py", line 179, in deco
    return f(*a, **kw)
  File "/home/april/spark-3.5.1-bin-hadoop3/python/lib/py4j-0.10.9.7-src.zip/py4j/protocol.py", line 334, in get_return_value
    raise Py4JError(
py4j.protocol.Py4JError: An error occurred while calling o12.sc
2024-06-05 00:02:55,662 Closing down clientserver connection
2024-06-05 00:02:55,662 Exception while sending command.
Traceback (most recent call last):
  File "/home/april/spark-3.5.1-bin-hadoop3/python/lib/py4j-0.10.9.7-src.zip/py4j/clientserver.py", line 511, in send_command
    answer = smart_decode(self.stream.readline()[:-1])
  File "/usr/lib/python3.10/socket.py", line 705, in readinto
    return self._sock.recv_into(b)
  File "/home/april/spark-3.5.1-bin-hadoop3/python/lib/pyspark.zip/pyspark/context.py", line 381, in signal_handler
    self.cancelAllJobs()
  File "/home/april/spark-3.5.1-bin-hadoop3/python/lib/pyspark.zip/pyspark/context.py", line 2446, in cancelAllJobs
    self._jsc.sc().cancelAllJobs()
  File "/home/april/spark-3.5.1-bin-hadoop3/python/lib/py4j-0.10.9.7-src.zip/py4j/java_gateway.py", line 1322, in __call__
    return_value = get_return_value(
  File "/home/april/spark-3.5.1-bin-hadoop3/python/lib/pyspark.zip/pyspark/errors/exceptions/captured.py", line 179, in deco
    return f(*a, **kw)
  File "/home/april/spark-3.5.1-bin-hadoop3/python/lib/py4j-0.10.9.7-src.zip/py4j/protocol.py", line 334, in get_return_value
    raise Py4JError(
py4j.protocol.Py4JError: An error occurred while calling o12.sc

During handling of the above exception, another exception occurred:

Traceback (most recent call last):
  File "/home/april/spark-3.5.1-bin-hadoop3/python/lib/py4j-0.10.9.7-src.zip/py4j/java_gateway.py", line 1038, in send_command
    response = connection.send_command(command)
  File "/home/april/spark-3.5.1-bin-hadoop3/python/lib/py4j-0.10.9.7-src.zip/py4j/clientserver.py", line 539, in send_command
    raise Py4JNetworkError(
py4j.protocol.Py4JNetworkError: Error while sending or receiving
2024-06-05 00:02:55,662 Closing down clientserver connection
2024-06-05 00:02:55,733 Closing down clientserver connection
2024-06-05 00:03:17,804 Callback Server Starting
2024-06-05 00:03:17,804 Socket listening on ('127.0.0.1', 44891)
2024-06-05 00:03:49,257 Python Server ready to receive messages
2024-06-05 00:03:49,257 Received command c on object id p0
2024-06-05 00:03:54,592 There was an exception while executing the Python Proxy on the Python Side.
Traceback (most recent call last):
  File "/home/april/spark-3.5.1-bin-hadoop3/python/lib/py4j-0.10.9.7-src.zip/py4j/clientserver.py", line 617, in _call_proxy
    return_value = getattr(self.pool[obj_id], method)(*params)
  File "/home/april/spark-3.5.1-bin-hadoop3/python/lib/pyspark.zip/pyspark/sql/utils.py", line 120, in call
    raise e
  File "/home/april/spark-3.5.1-bin-hadoop3/python/lib/pyspark.zip/pyspark/sql/utils.py", line 117, in call
    self.func(DataFrame(jdf, wrapped_session_jdf), batch_id)
  File "/home/april/BigDataLab03/TrendingArrivals.py", line 138, in detect_spikes
    goldman_spike = goldman_count >= 2 * previous_state[window_end]['goldman']
KeyError: datetime.datetime(2015, 12, 1, 0, 20)
2024-06-05 00:03:54,937 Closing down clientserver connection
2024-06-05 00:05:52,091 Callback Server Starting
2024-06-05 00:05:52,092 Socket listening on ('127.0.0.1', 33103)
2024-06-05 00:06:19,048 Python Server ready to receive messages
2024-06-05 00:06:19,049 Received command c on object id p0
2024-06-05 00:06:24,314 There was an exception while executing the Python Proxy on the Python Side.
Traceback (most recent call last):
  File "/home/april/spark-3.5.1-bin-hadoop3/python/lib/py4j-0.10.9.7-src.zip/py4j/clientserver.py", line 617, in _call_proxy
    return_value = getattr(self.pool[obj_id], method)(*params)
  File "/home/april/spark-3.5.1-bin-hadoop3/python/lib/pyspark.zip/pyspark/sql/utils.py", line 120, in call
    raise e
  File "/home/april/spark-3.5.1-bin-hadoop3/python/lib/pyspark.zip/pyspark/sql/utils.py", line 117, in call
    self.func(DataFrame(jdf, wrapped_session_jdf), batch_id)
  File "/home/april/BigDataLab03/TrendingArrivals.py", line 138, in detect_spikes
    goldman_spike = goldman_count >= 2 * previous_state[window_end]['goldman']
KeyError: datetime.datetime(2015, 12, 1, 0, 20)
2024-06-05 00:06:24,643 Closing down clientserver connection
2024-06-05 00:08:04,265 Callback Server Starting
2024-06-05 00:08:04,265 Socket listening on ('127.0.0.1', 46491)
2024-06-05 00:08:36,820 Python Server ready to receive messages
2024-06-05 00:08:36,821 Received command c on object id p0
2024-06-05 00:09:10,462 Error while receiving.
Traceback (most recent call last):
  File "/home/april/spark-3.5.1-bin-hadoop3/python/lib/py4j-0.10.9.7-src.zip/py4j/clientserver.py", line 511, in send_command
    answer = smart_decode(self.stream.readline()[:-1])
RuntimeError: reentrant call inside <_io.BufferedReader name=4>
2024-06-05 00:09:10,462 Closing down clientserver connection
2024-06-05 00:09:10,463 Exception while sending command.
Traceback (most recent call last):
  File "/home/april/spark-3.5.1-bin-hadoop3/python/lib/py4j-0.10.9.7-src.zip/py4j/clientserver.py", line 511, in send_command
    answer = smart_decode(self.stream.readline()[:-1])
RuntimeError: reentrant call inside <_io.BufferedReader name=4>

During handling of the above exception, another exception occurred:

Traceback (most recent call last):
  File "/home/april/spark-3.5.1-bin-hadoop3/python/lib/py4j-0.10.9.7-src.zip/py4j/java_gateway.py", line 1038, in send_command
    response = connection.send_command(command)
  File "/home/april/spark-3.5.1-bin-hadoop3/python/lib/py4j-0.10.9.7-src.zip/py4j/clientserver.py", line 539, in send_command
    raise Py4JNetworkError(
py4j.protocol.Py4JNetworkError: Error while sending or receiving
2024-06-05 00:09:10,465 Error while receiving.
Traceback (most recent call last):
  File "/home/april/spark-3.5.1-bin-hadoop3/python/lib/py4j-0.10.9.7-src.zip/py4j/clientserver.py", line 511, in send_command
    answer = smart_decode(self.stream.readline()[:-1])
  File "/usr/lib/python3.10/socket.py", line 705, in readinto
    return self._sock.recv_into(b)
  File "/home/april/spark-3.5.1-bin-hadoop3/python/lib/pyspark.zip/pyspark/context.py", line 381, in signal_handler
    self.cancelAllJobs()
  File "/home/april/spark-3.5.1-bin-hadoop3/python/lib/pyspark.zip/pyspark/context.py", line 2446, in cancelAllJobs
    self._jsc.sc().cancelAllJobs()
  File "/home/april/spark-3.5.1-bin-hadoop3/python/lib/py4j-0.10.9.7-src.zip/py4j/java_gateway.py", line 1322, in __call__
    return_value = get_return_value(
  File "/home/april/spark-3.5.1-bin-hadoop3/python/lib/pyspark.zip/pyspark/errors/exceptions/captured.py", line 179, in deco
    return f(*a, **kw)
  File "/home/april/spark-3.5.1-bin-hadoop3/python/lib/py4j-0.10.9.7-src.zip/py4j/protocol.py", line 334, in get_return_value
    raise Py4JError(
py4j.protocol.Py4JError: An error occurred while calling o12.sc
2024-06-05 00:09:10,467 Closing down clientserver connection
2024-06-05 00:09:10,467 Exception while sending command.
Traceback (most recent call last):
  File "/home/april/spark-3.5.1-bin-hadoop3/python/lib/py4j-0.10.9.7-src.zip/py4j/clientserver.py", line 511, in send_command
    answer = smart_decode(self.stream.readline()[:-1])
  File "/usr/lib/python3.10/socket.py", line 705, in readinto
    return self._sock.recv_into(b)
  File "/home/april/spark-3.5.1-bin-hadoop3/python/lib/pyspark.zip/pyspark/context.py", line 381, in signal_handler
    self.cancelAllJobs()
  File "/home/april/spark-3.5.1-bin-hadoop3/python/lib/pyspark.zip/pyspark/context.py", line 2446, in cancelAllJobs
    self._jsc.sc().cancelAllJobs()
  File "/home/april/spark-3.5.1-bin-hadoop3/python/lib/py4j-0.10.9.7-src.zip/py4j/java_gateway.py", line 1322, in __call__
    return_value = get_return_value(
  File "/home/april/spark-3.5.1-bin-hadoop3/python/lib/pyspark.zip/pyspark/errors/exceptions/captured.py", line 179, in deco
    return f(*a, **kw)
  File "/home/april/spark-3.5.1-bin-hadoop3/python/lib/py4j-0.10.9.7-src.zip/py4j/protocol.py", line 334, in get_return_value
    raise Py4JError(
py4j.protocol.Py4JError: An error occurred while calling o12.sc

During handling of the above exception, another exception occurred:

Traceback (most recent call last):
  File "/home/april/spark-3.5.1-bin-hadoop3/python/lib/py4j-0.10.9.7-src.zip/py4j/java_gateway.py", line 1038, in send_command
    response = connection.send_command(command)
  File "/home/april/spark-3.5.1-bin-hadoop3/python/lib/py4j-0.10.9.7-src.zip/py4j/clientserver.py", line 539, in send_command
    raise Py4JNetworkError(
py4j.protocol.Py4JNetworkError: Error while sending or receiving
2024-06-05 00:09:10,467 Closing down clientserver connection
2024-06-05 00:09:10,537 Closing down clientserver connection
2024-06-05 00:09:19,030 Callback Server Starting
2024-06-05 00:09:19,031 Socket listening on ('127.0.0.1', 44445)
2024-06-05 00:09:52,999 Python Server ready to receive messages
2024-06-05 00:09:52,999 Received command c on object id p0
2024-06-05 00:10:33,632 Error while receiving.
Traceback (most recent call last):
  File "/home/april/spark-3.5.1-bin-hadoop3/python/lib/py4j-0.10.9.7-src.zip/py4j/clientserver.py", line 511, in send_command
    answer = smart_decode(self.stream.readline()[:-1])
RuntimeError: reentrant call inside <_io.BufferedReader name=4>
2024-06-05 00:10:33,633 Closing down clientserver connection
2024-06-05 00:10:33,633 Exception while sending command.
Traceback (most recent call last):
  File "/home/april/spark-3.5.1-bin-hadoop3/python/lib/py4j-0.10.9.7-src.zip/py4j/clientserver.py", line 511, in send_command
    answer = smart_decode(self.stream.readline()[:-1])
RuntimeError: reentrant call inside <_io.BufferedReader name=4>

During handling of the above exception, another exception occurred:

Traceback (most recent call last):
  File "/home/april/spark-3.5.1-bin-hadoop3/python/lib/py4j-0.10.9.7-src.zip/py4j/java_gateway.py", line 1038, in send_command
    response = connection.send_command(command)
  File "/home/april/spark-3.5.1-bin-hadoop3/python/lib/py4j-0.10.9.7-src.zip/py4j/clientserver.py", line 539, in send_command
    raise Py4JNetworkError(
py4j.protocol.Py4JNetworkError: Error while sending or receiving
2024-06-05 00:10:33,636 Error while receiving.
Traceback (most recent call last):
  File "/home/april/spark-3.5.1-bin-hadoop3/python/lib/py4j-0.10.9.7-src.zip/py4j/clientserver.py", line 511, in send_command
    answer = smart_decode(self.stream.readline()[:-1])
  File "/usr/lib/python3.10/socket.py", line 705, in readinto
    return self._sock.recv_into(b)
  File "/home/april/spark-3.5.1-bin-hadoop3/python/lib/pyspark.zip/pyspark/context.py", line 381, in signal_handler
    self.cancelAllJobs()
  File "/home/april/spark-3.5.1-bin-hadoop3/python/lib/pyspark.zip/pyspark/context.py", line 2446, in cancelAllJobs
    self._jsc.sc().cancelAllJobs()
  File "/home/april/spark-3.5.1-bin-hadoop3/python/lib/py4j-0.10.9.7-src.zip/py4j/java_gateway.py", line 1322, in __call__
    return_value = get_return_value(
  File "/home/april/spark-3.5.1-bin-hadoop3/python/lib/pyspark.zip/pyspark/errors/exceptions/captured.py", line 179, in deco
    return f(*a, **kw)
  File "/home/april/spark-3.5.1-bin-hadoop3/python/lib/py4j-0.10.9.7-src.zip/py4j/protocol.py", line 334, in get_return_value
    raise Py4JError(
py4j.protocol.Py4JError: An error occurred while calling o12.sc
2024-06-05 00:10:33,637 Closing down clientserver connection
2024-06-05 00:10:33,638 Exception while sending command.
Traceback (most recent call last):
  File "/home/april/spark-3.5.1-bin-hadoop3/python/lib/py4j-0.10.9.7-src.zip/py4j/clientserver.py", line 511, in send_command
    answer = smart_decode(self.stream.readline()[:-1])
  File "/usr/lib/python3.10/socket.py", line 705, in readinto
    return self._sock.recv_into(b)
  File "/home/april/spark-3.5.1-bin-hadoop3/python/lib/pyspark.zip/pyspark/context.py", line 381, in signal_handler
    self.cancelAllJobs()
  File "/home/april/spark-3.5.1-bin-hadoop3/python/lib/pyspark.zip/pyspark/context.py", line 2446, in cancelAllJobs
    self._jsc.sc().cancelAllJobs()
  File "/home/april/spark-3.5.1-bin-hadoop3/python/lib/py4j-0.10.9.7-src.zip/py4j/java_gateway.py", line 1322, in __call__
    return_value = get_return_value(
  File "/home/april/spark-3.5.1-bin-hadoop3/python/lib/pyspark.zip/pyspark/errors/exceptions/captured.py", line 179, in deco
    return f(*a, **kw)
  File "/home/april/spark-3.5.1-bin-hadoop3/python/lib/py4j-0.10.9.7-src.zip/py4j/protocol.py", line 334, in get_return_value
    raise Py4JError(
py4j.protocol.Py4JError: An error occurred while calling o12.sc

During handling of the above exception, another exception occurred:

Traceback (most recent call last):
  File "/home/april/spark-3.5.1-bin-hadoop3/python/lib/py4j-0.10.9.7-src.zip/py4j/java_gateway.py", line 1038, in send_command
    response = connection.send_command(command)
  File "/home/april/spark-3.5.1-bin-hadoop3/python/lib/py4j-0.10.9.7-src.zip/py4j/clientserver.py", line 539, in send_command
    raise Py4JNetworkError(
py4j.protocol.Py4JNetworkError: Error while sending or receiving
2024-06-05 00:10:33,638 Closing down clientserver connection
2024-06-05 00:10:33,712 Closing down clientserver connection
2024-06-05 00:10:43,969 Callback Server Starting
2024-06-05 00:10:43,970 Socket listening on ('127.0.0.1', 38749)
2024-06-05 00:11:23,838 Python Server ready to receive messages
2024-06-05 00:11:23,839 Received command c on object id p0
2024-06-05 00:12:10,175 Error while receiving.
Traceback (most recent call last):
  File "/home/april/spark-3.5.1-bin-hadoop3/python/lib/py4j-0.10.9.7-src.zip/py4j/clientserver.py", line 511, in send_command
    answer = smart_decode(self.stream.readline()[:-1])
RuntimeError: reentrant call inside <_io.BufferedReader name=4>
2024-06-05 00:12:10,176 Closing down clientserver connection
2024-06-05 00:12:10,176 Exception while sending command.
Traceback (most recent call last):
  File "/home/april/spark-3.5.1-bin-hadoop3/python/lib/py4j-0.10.9.7-src.zip/py4j/clientserver.py", line 511, in send_command
    answer = smart_decode(self.stream.readline()[:-1])
RuntimeError: reentrant call inside <_io.BufferedReader name=4>

During handling of the above exception, another exception occurred:

Traceback (most recent call last):
  File "/home/april/spark-3.5.1-bin-hadoop3/python/lib/py4j-0.10.9.7-src.zip/py4j/java_gateway.py", line 1038, in send_command
    response = connection.send_command(command)
  File "/home/april/spark-3.5.1-bin-hadoop3/python/lib/py4j-0.10.9.7-src.zip/py4j/clientserver.py", line 539, in send_command
    raise Py4JNetworkError(
py4j.protocol.Py4JNetworkError: Error while sending or receiving
2024-06-05 00:12:10,179 Error while receiving.
Traceback (most recent call last):
  File "/home/april/spark-3.5.1-bin-hadoop3/python/lib/py4j-0.10.9.7-src.zip/py4j/clientserver.py", line 511, in send_command
    answer = smart_decode(self.stream.readline()[:-1])
  File "/usr/lib/python3.10/socket.py", line 705, in readinto
    return self._sock.recv_into(b)
  File "/home/april/spark-3.5.1-bin-hadoop3/python/lib/pyspark.zip/pyspark/context.py", line 381, in signal_handler
    self.cancelAllJobs()
  File "/home/april/spark-3.5.1-bin-hadoop3/python/lib/pyspark.zip/pyspark/context.py", line 2446, in cancelAllJobs
    self._jsc.sc().cancelAllJobs()
  File "/home/april/spark-3.5.1-bin-hadoop3/python/lib/py4j-0.10.9.7-src.zip/py4j/java_gateway.py", line 1322, in __call__
    return_value = get_return_value(
  File "/home/april/spark-3.5.1-bin-hadoop3/python/lib/pyspark.zip/pyspark/errors/exceptions/captured.py", line 179, in deco
    return f(*a, **kw)
  File "/home/april/spark-3.5.1-bin-hadoop3/python/lib/py4j-0.10.9.7-src.zip/py4j/protocol.py", line 334, in get_return_value
    raise Py4JError(
py4j.protocol.Py4JError: An error occurred while calling o12.sc
2024-06-05 00:12:10,181 Closing down clientserver connection
2024-06-05 00:12:10,181 Exception while sending command.
Traceback (most recent call last):
  File "/home/april/spark-3.5.1-bin-hadoop3/python/lib/py4j-0.10.9.7-src.zip/py4j/clientserver.py", line 511, in send_command
    answer = smart_decode(self.stream.readline()[:-1])
  File "/usr/lib/python3.10/socket.py", line 705, in readinto
    return self._sock.recv_into(b)
  File "/home/april/spark-3.5.1-bin-hadoop3/python/lib/pyspark.zip/pyspark/context.py", line 381, in signal_handler
    self.cancelAllJobs()
  File "/home/april/spark-3.5.1-bin-hadoop3/python/lib/pyspark.zip/pyspark/context.py", line 2446, in cancelAllJobs
    self._jsc.sc().cancelAllJobs()
  File "/home/april/spark-3.5.1-bin-hadoop3/python/lib/py4j-0.10.9.7-src.zip/py4j/java_gateway.py", line 1322, in __call__
    return_value = get_return_value(
  File "/home/april/spark-3.5.1-bin-hadoop3/python/lib/pyspark.zip/pyspark/errors/exceptions/captured.py", line 179, in deco
    return f(*a, **kw)
  File "/home/april/spark-3.5.1-bin-hadoop3/python/lib/py4j-0.10.9.7-src.zip/py4j/protocol.py", line 334, in get_return_value
    raise Py4JError(
py4j.protocol.Py4JError: An error occurred while calling o12.sc

During handling of the above exception, another exception occurred:

Traceback (most recent call last):
  File "/home/april/spark-3.5.1-bin-hadoop3/python/lib/py4j-0.10.9.7-src.zip/py4j/java_gateway.py", line 1038, in send_command
    response = connection.send_command(command)
  File "/home/april/spark-3.5.1-bin-hadoop3/python/lib/py4j-0.10.9.7-src.zip/py4j/clientserver.py", line 539, in send_command
    raise Py4JNetworkError(
py4j.protocol.Py4JNetworkError: Error while sending or receiving
2024-06-05 00:12:10,181 Closing down clientserver connection
2024-06-05 00:12:10,258 Closing down clientserver connection
2024-06-05 00:12:18,644 Callback Server Starting
2024-06-05 00:12:18,645 Socket listening on ('127.0.0.1', 33399)
2024-06-05 00:12:53,096 Python Server ready to receive messages
2024-06-05 00:12:53,096 Received command c on object id p0
2024-06-05 00:16:06,125 Error while receiving.
Traceback (most recent call last):
  File "/home/april/spark-3.5.1-bin-hadoop3/python/lib/py4j-0.10.9.7-src.zip/py4j/clientserver.py", line 511, in send_command
    answer = smart_decode(self.stream.readline()[:-1])
RuntimeError: reentrant call inside <_io.BufferedReader name=4>
2024-06-05 00:16:06,125 Closing down clientserver connection
2024-06-05 00:16:06,126 Exception while sending command.
Traceback (most recent call last):
  File "/home/april/spark-3.5.1-bin-hadoop3/python/lib/py4j-0.10.9.7-src.zip/py4j/clientserver.py", line 511, in send_command
    answer = smart_decode(self.stream.readline()[:-1])
RuntimeError: reentrant call inside <_io.BufferedReader name=4>

During handling of the above exception, another exception occurred:

Traceback (most recent call last):
  File "/home/april/spark-3.5.1-bin-hadoop3/python/lib/py4j-0.10.9.7-src.zip/py4j/java_gateway.py", line 1038, in send_command
    response = connection.send_command(command)
  File "/home/april/spark-3.5.1-bin-hadoop3/python/lib/py4j-0.10.9.7-src.zip/py4j/clientserver.py", line 539, in send_command
    raise Py4JNetworkError(
py4j.protocol.Py4JNetworkError: Error while sending or receiving
2024-06-05 00:16:06,128 Error while receiving.
Traceback (most recent call last):
  File "/home/april/spark-3.5.1-bin-hadoop3/python/lib/py4j-0.10.9.7-src.zip/py4j/clientserver.py", line 511, in send_command
    answer = smart_decode(self.stream.readline()[:-1])
  File "/usr/lib/python3.10/socket.py", line 705, in readinto
    return self._sock.recv_into(b)
  File "/home/april/spark-3.5.1-bin-hadoop3/python/lib/pyspark.zip/pyspark/context.py", line 381, in signal_handler
    self.cancelAllJobs()
  File "/home/april/spark-3.5.1-bin-hadoop3/python/lib/pyspark.zip/pyspark/context.py", line 2446, in cancelAllJobs
    self._jsc.sc().cancelAllJobs()
  File "/home/april/spark-3.5.1-bin-hadoop3/python/lib/py4j-0.10.9.7-src.zip/py4j/java_gateway.py", line 1322, in __call__
    return_value = get_return_value(
  File "/home/april/spark-3.5.1-bin-hadoop3/python/lib/pyspark.zip/pyspark/errors/exceptions/captured.py", line 179, in deco
    return f(*a, **kw)
  File "/home/april/spark-3.5.1-bin-hadoop3/python/lib/py4j-0.10.9.7-src.zip/py4j/protocol.py", line 334, in get_return_value
    raise Py4JError(
py4j.protocol.Py4JError: An error occurred while calling o12.sc
2024-06-05 00:16:06,130 Closing down clientserver connection
2024-06-05 00:16:06,130 Exception while sending command.
Traceback (most recent call last):
  File "/home/april/spark-3.5.1-bin-hadoop3/python/lib/py4j-0.10.9.7-src.zip/py4j/clientserver.py", line 511, in send_command
    answer = smart_decode(self.stream.readline()[:-1])
  File "/usr/lib/python3.10/socket.py", line 705, in readinto
    return self._sock.recv_into(b)
  File "/home/april/spark-3.5.1-bin-hadoop3/python/lib/pyspark.zip/pyspark/context.py", line 381, in signal_handler
    self.cancelAllJobs()
  File "/home/april/spark-3.5.1-bin-hadoop3/python/lib/pyspark.zip/pyspark/context.py", line 2446, in cancelAllJobs
    self._jsc.sc().cancelAllJobs()
  File "/home/april/spark-3.5.1-bin-hadoop3/python/lib/py4j-0.10.9.7-src.zip/py4j/java_gateway.py", line 1322, in __call__
    return_value = get_return_value(
  File "/home/april/spark-3.5.1-bin-hadoop3/python/lib/pyspark.zip/pyspark/errors/exceptions/captured.py", line 179, in deco
    return f(*a, **kw)
  File "/home/april/spark-3.5.1-bin-hadoop3/python/lib/py4j-0.10.9.7-src.zip/py4j/protocol.py", line 334, in get_return_value
    raise Py4JError(
py4j.protocol.Py4JError: An error occurred while calling o12.sc

During handling of the above exception, another exception occurred:

Traceback (most recent call last):
  File "/home/april/spark-3.5.1-bin-hadoop3/python/lib/py4j-0.10.9.7-src.zip/py4j/java_gateway.py", line 1038, in send_command
    response = connection.send_command(command)
  File "/home/april/spark-3.5.1-bin-hadoop3/python/lib/py4j-0.10.9.7-src.zip/py4j/clientserver.py", line 539, in send_command
    raise Py4JNetworkError(
py4j.protocol.Py4JNetworkError: Error while sending or receiving
2024-06-05 00:16:06,130 Closing down clientserver connection
2024-06-05 00:16:06,174 Closing down clientserver connection
